2024-11-23 15:50:13,702 - ERROR - Erro ao gerar coluna de horários: Período inválido. Use o formato HHh-HHh (ex: 06h-16h).
2024-11-23 15:50:19,666 - ERROR - Erro ao gerar coluna de horários: Período inválido. Use o formato HHh-HHh (ex: 06h-16h).
2024-11-23 15:51:38,787 - ERROR - Erro ao criar sessão: time data 'Nenhuma data selecionada' does not match format '%d-%m-%Y'
2024-11-23 15:51:42,614 - ERROR - Erro ao criar sessão: time data 'Nenhuma data selecionada' does not match format '%d-%m-%Y'
2024-11-23 15:51:43,365 - ERROR - Erro ao criar sessão: time data 'Nenhuma data selecionada' does not match format '%d-%m-%Y'
2024-11-23 15:51:43,544 - ERROR - Erro ao criar sessão: time data 'Nenhuma data selecionada' does not match format '%d-%m-%Y'
2024-11-23 15:51:43,722 - ERROR - Erro ao criar sessão: time data 'Nenhuma data selecionada' does not match format '%d-%m-%Y'
2024-11-23 15:51:43,913 - ERROR - Erro ao criar sessão: time data 'Nenhuma data selecionada' does not match format '%d-%m-%Y'
2024-11-23 15:51:44,087 - ERROR - Erro ao criar sessão: time data 'Nenhuma data selecionada' does not match format '%d-%m-%Y'
2024-11-23 15:51:44,249 - ERROR - Erro ao criar sessão: time data 'Nenhuma data selecionada' does not match format '%d-%m-%Y'
2024-11-23 15:51:44,402 - ERROR - Erro ao criar sessão: time data 'Nenhuma data selecionada' does not match format '%d-%m-%Y'
2024-11-23 15:51:44,580 - ERROR - Erro ao criar sessão: time data 'Nenhuma data selecionada' does not match format '%d-%m-%Y'
2024-11-23 15:51:44,725 - ERROR - Erro ao criar sessão: time data 'Nenhuma data selecionada' does not match format '%d-%m-%Y'
2024-11-23 15:54:28,785 - ERROR - Erro ao gerar coluna de horários: Período inválido. Use o formato HHh-HHh (ex: 06h-16h).
2024-11-23 15:54:29,267 - ERROR - Erro ao salvar contagens: [Errno 13] Permission denied: 'Z:\\\\0Pesquisa\\\\_0ContadorDigital\\\\Contagens\\lucas.melo\\TesteHoras\\TesteHoras_TETETE_23-11-2024.xlsx'
2024-11-23 16:11:53,141 - ERROR - Erro ao criar sessão: Nenhuma categoria encontrada para o padrão selecionado.
2024-11-23 16:11:58,146 - ERROR - Erro ao criar sessão: Nenhuma categoria encontrada para o padrão selecionado.
2024-11-23 16:11:58,909 - ERROR - Erro ao criar sessão: Nenhuma categoria encontrada para o padrão selecionado.
2024-11-23 16:11:59,097 - ERROR - Erro ao criar sessão: Nenhuma categoria encontrada para o padrão selecionado.
2024-11-23 16:11:59,268 - ERROR - Erro ao criar sessão: Nenhuma categoria encontrada para o padrão selecionado.
2024-11-23 16:21:03,314 - ERROR - Erro ao salvar contagens: 'ContadorPerplan' object has no attribute 'horarios_df'
2024-11-23 16:21:11,066 - ERROR - Erro ao salvar contagens: 'ContadorPerplan' object has no attribute 'horarios_df'
2024-11-23 16:28:16,950 - ERROR - Erro: `horarios_df` não está inicializado ou está vazio.
2024-11-23 16:34:46,924 - ERROR - Erro: `horarios_df` não está inicializado ou está vazio.
2024-11-23 16:41:40,773 - ERROR - Erro ao salvar contagens: cannot access local variable 'ultima_linha_vazia' where it is not associated with a value
2024-11-23 16:50:44,811 - ERROR - Erro: `horarios_df` não está inicializado ou está vazio.
2024-11-23 16:51:08,459 - ERROR - Erro ao salvar contagens: File is not a zip file
2024-11-23 16:51:08,797 - ERROR - Erro: Não há horários disponíveis para salvar.
2024-11-23 16:51:08,930 - ERROR - Erro: Não há horários disponíveis para salvar.
2024-11-23 16:51:09,833 - ERROR - Erro ao salvar histórico: Method 'commit()' can't be called here; method '_prepare_impl()' is already in progress and this would cause an unexpected state change to <SessionTransactionState.CLOSED: 5> (Background on this error at: https://sqlalche.me/e/20/isce)
2024-11-23 16:51:09,833 - ERROR - Erro ao salvar contagens: Method 'rollback()' can't be called here; method '_prepare_impl()' is already in progress and this would cause an unexpected state change to <SessionTransactionState.CLOSED: 5> (Background on this error at: https://sqlalche.me/e/20/isce)
2024-11-23 16:51:09,848 - ERROR - Erro ao salvar histórico: This transaction is closed
2024-11-23 16:51:11,085 - ERROR - Erro: Não há horários disponíveis para salvar.
2024-11-23 16:51:14,263 - ERROR - Erro: Não há horários disponíveis para salvar.
2024-11-23 16:51:37,238 - ERROR - Erro: `horarios_df` não está inicializado ou está vazio.
2024-11-23 16:51:58,900 - ERROR - Erro: Não há horários disponíveis para salvar.
2024-11-23 17:00:51,741 - ERROR - Erro: Não há horários disponíveis para salvar.
2024-11-23 17:00:51,880 - ERROR - Erro: Não há horários disponíveis para salvar.
2024-11-23 17:07:44,947 - ERROR - Erro ao carregar tokens salvos: 'ContadorPerplan' object has no attribute 'carregar_padroes_selecionados'
2024-11-23 17:08:00,753 - ERROR - Erro ao carregar tokens salvos: 'ContadorPerplan' object has no attribute 'carregar_padroes_selecionados'
2024-11-23 17:10:13,312 - ERROR - Erro ao carregar tokens salvos: 'ContadorPerplan' object has no attribute 'carregar_padroes_selecionados'
2024-11-23 17:13:25,878 - ERROR - Erro: Não há horários disponíveis para salvar.
2024-11-26 15:18:24,973 - ERROR - Future exception was never retrieved
future: <Future finished exception=NameError("name 'Sessao' is not defined")>
Traceback (most recent call last):
  File "C:\Users\lucas.melo\AppData\Local\Programs\Python\Python312\Lib\concurrent\futures\thread.py", line 58, in run
    result = self.fn(*self.args, **self.kwargs)
             ^^^^^^^^^^^^^^^^^^^^^^^^^^^^^^^^^^
  File "C:\Users\lucas.melo\traffic-count\venv\Lib\site-packages\flet_core\page.py", line 944, in wrapper
    handler(*args)
  File "C:\Users\lucas.melo\traffic-count\frontend\main.py", line 756, in <lambda>
    config_button = ft.ElevatedButton(text="Configurar Binds", on_click=lambda e: change_binds(self.page, self))
                                                                                  ^^^^^^^^^^^^^^^^^^^^^^^^^^^^^
  File "C:\Users\lucas.melo\traffic-count\frontend\utils\change_binds.py", line 13, in change_binds
    sessao_ativa = contador.session.query(Sessao).filter_by(sessao=contador.sessao).first()
                                          ^^^^^^
NameError: name 'Sessao' is not defined. Did you mean: 'Session'?
2024-11-26 15:18:30,000 - ERROR - Future exception was never retrieved
future: <Future finished exception=NameError("name 'Sessao' is not defined")>
Traceback (most recent call last):
  File "C:\Users\lucas.melo\AppData\Local\Programs\Python\Python312\Lib\concurrent\futures\thread.py", line 58, in run
    result = self.fn(*self.args, **self.kwargs)
             ^^^^^^^^^^^^^^^^^^^^^^^^^^^^^^^^^^
  File "C:\Users\lucas.melo\traffic-count\venv\Lib\site-packages\flet_core\page.py", line 944, in wrapper
    handler(*args)
  File "C:\Users\lucas.melo\traffic-count\frontend\main.py", line 756, in <lambda>
    config_button = ft.ElevatedButton(text="Configurar Binds", on_click=lambda e: change_binds(self.page, self))
                                                                                  ^^^^^^^^^^^^^^^^^^^^^^^^^^^^^
  File "C:\Users\lucas.melo\traffic-count\frontend\utils\change_binds.py", line 13, in change_binds
    sessao_ativa = contador.session.query(Sessao).filter_by(sessao=contador.sessao).first()
                                          ^^^^^^
NameError: name 'Sessao' is not defined. Did you mean: 'Session'?
2024-11-26 15:18:31,925 - ERROR - Future exception was never retrieved
future: <Future finished exception=NameError("name 'Sessao' is not defined")>
Traceback (most recent call last):
  File "C:\Users\lucas.melo\AppData\Local\Programs\Python\Python312\Lib\concurrent\futures\thread.py", line 58, in run
    result = self.fn(*self.args, **self.kwargs)
             ^^^^^^^^^^^^^^^^^^^^^^^^^^^^^^^^^^
  File "C:\Users\lucas.melo\traffic-count\venv\Lib\site-packages\flet_core\page.py", line 944, in wrapper
    handler(*args)
  File "C:\Users\lucas.melo\traffic-count\frontend\main.py", line 756, in <lambda>
    config_button = ft.ElevatedButton(text="Configurar Binds", on_click=lambda e: change_binds(self.page, self))
                                                                                  ^^^^^^^^^^^^^^^^^^^^^^^^^^^^^
  File "C:\Users\lucas.melo\traffic-count\frontend\utils\change_binds.py", line 13, in change_binds
    sessao_ativa = contador.session.query(Sessao).filter_by(sessao=contador.sessao).first()
                                          ^^^^^^
NameError: name 'Sessao' is not defined. Did you mean: 'Session'?
2024-11-26 15:18:32,112 - ERROR - Future exception was never retrieved
future: <Future finished exception=NameError("name 'Sessao' is not defined")>
Traceback (most recent call last):
  File "C:\Users\lucas.melo\AppData\Local\Programs\Python\Python312\Lib\concurrent\futures\thread.py", line 58, in run
    result = self.fn(*self.args, **self.kwargs)
             ^^^^^^^^^^^^^^^^^^^^^^^^^^^^^^^^^^
  File "C:\Users\lucas.melo\traffic-count\venv\Lib\site-packages\flet_core\page.py", line 944, in wrapper
    handler(*args)
  File "C:\Users\lucas.melo\traffic-count\frontend\main.py", line 756, in <lambda>
    config_button = ft.ElevatedButton(text="Configurar Binds", on_click=lambda e: change_binds(self.page, self))
                                                                                  ^^^^^^^^^^^^^^^^^^^^^^^^^^^^^
  File "C:\Users\lucas.melo\traffic-count\frontend\utils\change_binds.py", line 13, in change_binds
    sessao_ativa = contador.session.query(Sessao).filter_by(sessao=contador.sessao).first()
                                          ^^^^^^
NameError: name 'Sessao' is not defined. Did you mean: 'Session'?
2024-11-26 18:12:38,606 - ERROR - Future exception was never retrieved
future: <Future finished exception=AssertionError('RegisterPage Control must be added to the page first')>
Traceback (most recent call last):
  File "C:\Users\lucas.melo\traffic-count\frontend\auth\register.py", line 103, in register
    self.update()
  File "C:\Users\lucas.melo\traffic-count\venv\Lib\site-packages\flet_core\control.py", line 308, in update
    self.__page
AssertionError: RegisterPage Control must be added to the page first

During handling of the above exception, another exception occurred:

Traceback (most recent call last):
  File "C:\Users\lucas.melo\AppData\Local\Programs\Python\Python312\Lib\concurrent\futures\thread.py", line 58, in run
    result = self.fn(*self.args, **self.kwargs)
             ^^^^^^^^^^^^^^^^^^^^^^^^^^^^^^^^^^
  File "C:\Users\lucas.melo\traffic-count\venv\Lib\site-packages\flet_core\page.py", line 944, in wrapper
    handler(*args)
  File "C:\Users\lucas.melo\traffic-count\frontend\auth\register.py", line 130, in register
    self.update()
  File "C:\Users\lucas.melo\traffic-count\venv\Lib\site-packages\flet_core\control.py", line 308, in update
    self.__page
AssertionError: RegisterPage Control must be added to the page first
2024-11-26 18:14:23,414 - ERROR - Future exception was never retrieved
future: <Future finished exception=AttributeError("'RegisterPage' object has no attribute 'register'")>
Traceback (most recent call last):
  File "C:\Users\lucas.melo\AppData\Local\Programs\Python\Python312\Lib\concurrent\futures\thread.py", line 58, in run
    result = self.fn(*self.args, **self.kwargs)
             ^^^^^^^^^^^^^^^^^^^^^^^^^^^^^^^^^^
  File "C:\Users\lucas.melo\traffic-count\venv\Lib\site-packages\flet_core\page.py", line 944, in wrapper
    handler(*args)
  File "C:\Users\lucas.melo\traffic-count\frontend\auth\login.py", line 101, in show_register
    self.app.show_register_page()
  File "C:\Users\lucas.melo\traffic-count\frontend\main.py", line 1003, in show_register_page
    self.page.add(RegisterPage(self))
                  ^^^^^^^^^^^^^^^^^^
  File "C:\Users\lucas.melo\traffic-count\frontend\auth\register.py", line 31, in __init__
    self.register_button = ft.ElevatedButton("Registrar", on_click=self.register)
                                                                   ^^^^^^^^^^^^^
AttributeError: 'RegisterPage' object has no attribute 'register'
