2024-11-23 15:50:13,702 - ERROR - Erro ao gerar coluna de horários: Período inválido. Use o formato HHh-HHh (ex: 06h-16h).
2024-11-23 15:50:19,666 - ERROR - Erro ao gerar coluna de horários: Período inválido. Use o formato HHh-HHh (ex: 06h-16h).
2024-11-23 15:51:38,787 - ERROR - Erro ao criar sessão: time data 'Nenhuma data selecionada' does not match format '%d-%m-%Y'
2024-11-23 15:51:42,614 - ERROR - Erro ao criar sessão: time data 'Nenhuma data selecionada' does not match format '%d-%m-%Y'
2024-11-23 15:51:43,365 - ERROR - Erro ao criar sessão: time data 'Nenhuma data selecionada' does not match format '%d-%m-%Y'
2024-11-23 15:51:43,544 - ERROR - Erro ao criar sessão: time data 'Nenhuma data selecionada' does not match format '%d-%m-%Y'
2024-11-23 15:51:43,722 - ERROR - Erro ao criar sessão: time data 'Nenhuma data selecionada' does not match format '%d-%m-%Y'
2024-11-23 15:51:43,913 - ERROR - Erro ao criar sessão: time data 'Nenhuma data selecionada' does not match format '%d-%m-%Y'
2024-11-23 15:51:44,087 - ERROR - Erro ao criar sessão: time data 'Nenhuma data selecionada' does not match format '%d-%m-%Y'
2024-11-23 15:51:44,249 - ERROR - Erro ao criar sessão: time data 'Nenhuma data selecionada' does not match format '%d-%m-%Y'
2024-11-23 15:51:44,402 - ERROR - Erro ao criar sessão: time data 'Nenhuma data selecionada' does not match format '%d-%m-%Y'
2024-11-23 15:51:44,580 - ERROR - Erro ao criar sessão: time data 'Nenhuma data selecionada' does not match format '%d-%m-%Y'
2024-11-23 15:51:44,725 - ERROR - Erro ao criar sessão: time data 'Nenhuma data selecionada' does not match format '%d-%m-%Y'
2024-11-23 15:54:28,785 - ERROR - Erro ao gerar coluna de horários: Período inválido. Use o formato HHh-HHh (ex: 06h-16h).
2024-11-23 15:54:29,267 - ERROR - Erro ao salvar contagens: [Errno 13] Permission denied: 'Z:\\\\0Pesquisa\\\\_0ContadorDigital\\\\Contagens\\lucas.melo\\TesteHoras\\TesteHoras_TETETE_23-11-2024.xlsx'
2024-11-23 16:11:53,141 - ERROR - Erro ao criar sessão: Nenhuma categoria encontrada para o padrão selecionado.
2024-11-23 16:11:58,146 - ERROR - Erro ao criar sessão: Nenhuma categoria encontrada para o padrão selecionado.
2024-11-23 16:11:58,909 - ERROR - Erro ao criar sessão: Nenhuma categoria encontrada para o padrão selecionado.
2024-11-23 16:11:59,097 - ERROR - Erro ao criar sessão: Nenhuma categoria encontrada para o padrão selecionado.
2024-11-23 16:11:59,268 - ERROR - Erro ao criar sessão: Nenhuma categoria encontrada para o padrão selecionado.
2024-11-23 16:21:03,314 - ERROR - Erro ao salvar contagens: 'ContadorPerplan' object has no attribute 'horarios_df'
2024-11-23 16:21:11,066 - ERROR - Erro ao salvar contagens: 'ContadorPerplan' object has no attribute 'horarios_df'
2024-11-23 16:28:16,950 - ERROR - Erro: `horarios_df` não está inicializado ou está vazio.
2024-11-23 16:34:46,924 - ERROR - Erro: `horarios_df` não está inicializado ou está vazio.
2024-11-23 16:41:40,773 - ERROR - Erro ao salvar contagens: cannot access local variable 'ultima_linha_vazia' where it is not associated with a value
2024-11-23 16:50:44,811 - ERROR - Erro: `horarios_df` não está inicializado ou está vazio.
2024-11-23 16:51:08,459 - ERROR - Erro ao salvar contagens: File is not a zip file
2024-11-23 16:51:08,797 - ERROR - Erro: Não há horários disponíveis para salvar.
2024-11-23 16:51:08,930 - ERROR - Erro: Não há horários disponíveis para salvar.
2024-11-23 16:51:09,833 - ERROR - Erro ao salvar histórico: Method 'commit()' can't be called here; method '_prepare_impl()' is already in progress and this would cause an unexpected state change to <SessionTransactionState.CLOSED: 5> (Background on this error at: https://sqlalche.me/e/20/isce)
2024-11-23 16:51:09,833 - ERROR - Erro ao salvar contagens: Method 'rollback()' can't be called here; method '_prepare_impl()' is already in progress and this would cause an unexpected state change to <SessionTransactionState.CLOSED: 5> (Background on this error at: https://sqlalche.me/e/20/isce)
2024-11-23 16:51:09,848 - ERROR - Erro ao salvar histórico: This transaction is closed
2024-11-23 16:51:11,085 - ERROR - Erro: Não há horários disponíveis para salvar.
2024-11-23 16:51:14,263 - ERROR - Erro: Não há horários disponíveis para salvar.
2024-11-23 16:51:37,238 - ERROR - Erro: `horarios_df` não está inicializado ou está vazio.
2024-11-23 16:51:58,900 - ERROR - Erro: Não há horários disponíveis para salvar.
2024-11-23 17:00:51,741 - ERROR - Erro: Não há horários disponíveis para salvar.
2024-11-23 17:00:51,880 - ERROR - Erro: Não há horários disponíveis para salvar.
2024-11-23 17:07:44,947 - ERROR - Erro ao carregar tokens salvos: 'ContadorPerplan' object has no attribute 'carregar_padroes_selecionados'
2024-11-23 17:08:00,753 - ERROR - Erro ao carregar tokens salvos: 'ContadorPerplan' object has no attribute 'carregar_padroes_selecionados'
2024-11-23 17:10:13,312 - ERROR - Erro ao carregar tokens salvos: 'ContadorPerplan' object has no attribute 'carregar_padroes_selecionados'
2024-11-23 17:13:25,878 - ERROR - Erro: Não há horários disponíveis para salvar.
2024-11-26 15:18:24,973 - ERROR - Future exception was never retrieved
future: <Future finished exception=NameError("name 'Sessao' is not defined")>
Traceback (most recent call last):
  File "C:\Users\lucas.melo\AppData\Local\Programs\Python\Python312\Lib\concurrent\futures\thread.py", line 58, in run
    result = self.fn(*self.args, **self.kwargs)
             ^^^^^^^^^^^^^^^^^^^^^^^^^^^^^^^^^^
  File "C:\Users\lucas.melo\traffic-count\venv\Lib\site-packages\flet_core\page.py", line 944, in wrapper
    handler(*args)
  File "C:\Users\lucas.melo\traffic-count\frontend\main.py", line 756, in <lambda>
    config_button = ft.ElevatedButton(text="Configurar Binds", on_click=lambda e: change_binds(self.page, self))
                                                                                  ^^^^^^^^^^^^^^^^^^^^^^^^^^^^^
  File "C:\Users\lucas.melo\traffic-count\frontend\utils\change_binds.py", line 13, in change_binds
    sessao_ativa = contador.session.query(Sessao).filter_by(sessao=contador.sessao).first()
                                          ^^^^^^
NameError: name 'Sessao' is not defined. Did you mean: 'Session'?
2024-11-26 15:18:30,000 - ERROR - Future exception was never retrieved
future: <Future finished exception=NameError("name 'Sessao' is not defined")>
Traceback (most recent call last):
  File "C:\Users\lucas.melo\AppData\Local\Programs\Python\Python312\Lib\concurrent\futures\thread.py", line 58, in run
    result = self.fn(*self.args, **self.kwargs)
             ^^^^^^^^^^^^^^^^^^^^^^^^^^^^^^^^^^
  File "C:\Users\lucas.melo\traffic-count\venv\Lib\site-packages\flet_core\page.py", line 944, in wrapper
    handler(*args)
  File "C:\Users\lucas.melo\traffic-count\frontend\main.py", line 756, in <lambda>
    config_button = ft.ElevatedButton(text="Configurar Binds", on_click=lambda e: change_binds(self.page, self))
                                                                                  ^^^^^^^^^^^^^^^^^^^^^^^^^^^^^
  File "C:\Users\lucas.melo\traffic-count\frontend\utils\change_binds.py", line 13, in change_binds
    sessao_ativa = contador.session.query(Sessao).filter_by(sessao=contador.sessao).first()
                                          ^^^^^^
NameError: name 'Sessao' is not defined. Did you mean: 'Session'?
2024-11-26 15:18:31,925 - ERROR - Future exception was never retrieved
future: <Future finished exception=NameError("name 'Sessao' is not defined")>
Traceback (most recent call last):
  File "C:\Users\lucas.melo\AppData\Local\Programs\Python\Python312\Lib\concurrent\futures\thread.py", line 58, in run
    result = self.fn(*self.args, **self.kwargs)
             ^^^^^^^^^^^^^^^^^^^^^^^^^^^^^^^^^^
  File "C:\Users\lucas.melo\traffic-count\venv\Lib\site-packages\flet_core\page.py", line 944, in wrapper
    handler(*args)
  File "C:\Users\lucas.melo\traffic-count\frontend\main.py", line 756, in <lambda>
    config_button = ft.ElevatedButton(text="Configurar Binds", on_click=lambda e: change_binds(self.page, self))
                                                                                  ^^^^^^^^^^^^^^^^^^^^^^^^^^^^^
  File "C:\Users\lucas.melo\traffic-count\frontend\utils\change_binds.py", line 13, in change_binds
    sessao_ativa = contador.session.query(Sessao).filter_by(sessao=contador.sessao).first()
                                          ^^^^^^
NameError: name 'Sessao' is not defined. Did you mean: 'Session'?
2024-11-26 15:18:32,112 - ERROR - Future exception was never retrieved
future: <Future finished exception=NameError("name 'Sessao' is not defined")>
Traceback (most recent call last):
  File "C:\Users\lucas.melo\AppData\Local\Programs\Python\Python312\Lib\concurrent\futures\thread.py", line 58, in run
    result = self.fn(*self.args, **self.kwargs)
             ^^^^^^^^^^^^^^^^^^^^^^^^^^^^^^^^^^
  File "C:\Users\lucas.melo\traffic-count\venv\Lib\site-packages\flet_core\page.py", line 944, in wrapper
    handler(*args)
  File "C:\Users\lucas.melo\traffic-count\frontend\main.py", line 756, in <lambda>
    config_button = ft.ElevatedButton(text="Configurar Binds", on_click=lambda e: change_binds(self.page, self))
                                                                                  ^^^^^^^^^^^^^^^^^^^^^^^^^^^^^
  File "C:\Users\lucas.melo\traffic-count\frontend\utils\change_binds.py", line 13, in change_binds
    sessao_ativa = contador.session.query(Sessao).filter_by(sessao=contador.sessao).first()
                                          ^^^^^^
NameError: name 'Sessao' is not defined. Did you mean: 'Session'?
2024-11-26 18:12:38,606 - ERROR - Future exception was never retrieved
future: <Future finished exception=AssertionError('RegisterPage Control must be added to the page first')>
Traceback (most recent call last):
  File "C:\Users\lucas.melo\traffic-count\frontend\auth\register.py", line 103, in register
    self.update()
  File "C:\Users\lucas.melo\traffic-count\venv\Lib\site-packages\flet_core\control.py", line 308, in update
    self.__page
AssertionError: RegisterPage Control must be added to the page first

During handling of the above exception, another exception occurred:

Traceback (most recent call last):
  File "C:\Users\lucas.melo\AppData\Local\Programs\Python\Python312\Lib\concurrent\futures\thread.py", line 58, in run
    result = self.fn(*self.args, **self.kwargs)
             ^^^^^^^^^^^^^^^^^^^^^^^^^^^^^^^^^^
  File "C:\Users\lucas.melo\traffic-count\venv\Lib\site-packages\flet_core\page.py", line 944, in wrapper
    handler(*args)
  File "C:\Users\lucas.melo\traffic-count\frontend\auth\register.py", line 130, in register
    self.update()
  File "C:\Users\lucas.melo\traffic-count\venv\Lib\site-packages\flet_core\control.py", line 308, in update
    self.__page
AssertionError: RegisterPage Control must be added to the page first
2024-11-26 18:14:23,414 - ERROR - Future exception was never retrieved
future: <Future finished exception=AttributeError("'RegisterPage' object has no attribute 'register'")>
Traceback (most recent call last):
  File "C:\Users\lucas.melo\AppData\Local\Programs\Python\Python312\Lib\concurrent\futures\thread.py", line 58, in run
    result = self.fn(*self.args, **self.kwargs)
             ^^^^^^^^^^^^^^^^^^^^^^^^^^^^^^^^^^
  File "C:\Users\lucas.melo\traffic-count\venv\Lib\site-packages\flet_core\page.py", line 944, in wrapper
    handler(*args)
  File "C:\Users\lucas.melo\traffic-count\frontend\auth\login.py", line 101, in show_register
    self.app.show_register_page()
  File "C:\Users\lucas.melo\traffic-count\frontend\main.py", line 1003, in show_register_page
    self.page.add(RegisterPage(self))
                  ^^^^^^^^^^^^^^^^^^
  File "C:\Users\lucas.melo\traffic-count\frontend\auth\register.py", line 31, in __init__
    self.register_button = ft.ElevatedButton("Registrar", on_click=self.register)
                                                                   ^^^^^^^^^^^^^
AttributeError: 'RegisterPage' object has no attribute 'register'
2024-11-28 11:56:48,721 - ERROR - Erro: Não há horários disponíveis para o movimento 'A'.
2024-11-28 11:56:48,724 - ERROR - Erro: Não há horários disponíveis para o movimento 'B'.
2024-11-28 12:04:15,918 - ERROR - Erro ao salvar contagens: At least one sheet must be visible
2024-11-28 12:04:22,688 - ERROR - Erro ao salvar contagens: "There is no item named '[Content_Types].xml' in the archive"
2024-11-28 12:13:07,058 - ERROR - Arquivo Excel corrompido. Recriando arquivo...
2024-11-28 12:13:07,712 - ERROR - Erro ao salvar contagens: name 'load_workbook' is not defined
2024-11-28 12:16:00,591 - ERROR - Erro ao salvar contagens: Sheet 'A' already exists and if_sheet_exists is set to 'error'.
2024-11-28 12:19:34,165 - ERROR - Erro ao salvar contagens: Sheet 'A' already exists and if_sheet_exists is set to 'error'.
2024-11-28 12:23:01,626 - ERROR - Erro ao salvar contagens: if_sheet_exists is only valid in append mode (mode='a')
2024-11-28 12:23:05,275 - ERROR - Erro ao salvar contagens: if_sheet_exists is only valid in append mode (mode='a')
2024-11-28 12:42:20,271 - ERROR - Erro ao salvar contagens: Sheet 'A' already exists and if_sheet_exists is set to 'error'.
2024-11-28 12:42:27,347 - ERROR - Erro ao salvar contagens: Sheet 'A' already exists and if_sheet_exists is set to 'error'.
2024-11-28 12:42:29,391 - ERROR - Erro ao salvar contagens: Sheet 'A' already exists and if_sheet_exists is set to 'error'.
2024-11-28 12:44:10,626 - ERROR - Erro ao salvar contagens: [Errno 2] No such file or directory: 'Z:\\\\0Pesquisa\\\\_0ContadorDigital\\\\Contagens\\lucas.melo\\testesa\\testesa_p11_28-11-2024.xlsx'
2024-11-28 12:46:05,120 - ERROR - Erro ao salvar contagens: Sheet 'A' already exists and if_sheet_exists is set to 'error'.
2024-11-28 12:54:49,827 - ERROR - Erro ao salvar contagens: Sheet 'A' already exists and if_sheet_exists is set to 'error'.
2024-11-28 12:58:22,972 - ERROR - Erro ao salvar contagens: name 'openpyxl' is not defined
2024-11-28 14:17:20,480 - ERROR - Erro ao salvar contagens: [Errno 2] No such file or directory: 'Z:\\\\0Pesquisa\\\\_0ContadorDigital\\\\Contagens\\lucas.melo\\testesalvamento\\testesalvamento_p19_28-11-2024.xlsx'
2024-11-28 14:17:25,624 - ERROR - Erro ao salvar contagens: [Errno 2] No such file or directory: 'Z:\\\\0Pesquisa\\\\_0ContadorDigital\\\\Contagens\\lucas.melo\\testesalvamento\\testesalvamento_p19_28-11-2024.xlsx'
2024-11-28 14:19:10,815 - ERROR - Erro ao salvar contagens: [Errno 2] No such file or directory: 'Z:\\\\0Pesquisa\\\\_0ContadorDigital\\\\Contagens\\lucas.melo\\testesalvamento\\testesalvamento_p19_28-11-2024.xlsx'
2024-11-28 14:19:33,304 - ERROR - Nenhuma mudança nas contagens desde o último salvamento.
2024-11-28 14:19:43,446 - ERROR - Erro ao salvar contagens: [Errno 2] No such file or directory: 'Z:\\\\0Pesquisa\\\\_0ContadorDigital\\\\Contagens\\lucas.melo\\testesalvamento\\testesalvamento_p20_28-11-2024.xlsx'
2024-11-28 14:20:49,224 - ERROR - Erro ao salvar contagens: [Errno 2] No such file or directory: 'Z:\\\\0Pesquisa\\\\_0ContadorDigital\\\\Contagens\\lucas.melo\\testesalvamento\\testesalvamento_p20_28-11-2024.xlsx'
2024-11-28 14:21:14,309 - ERROR - Erro ao salvar contagens: [Errno 2] No such file or directory: 'Z:\\\\0Pesquisa\\\\_0ContadorDigital\\\\Contagens\\lucas.melo\\testesavalmento\\testesavalmento_p20_28-11-2024.xlsx'
2024-11-28 14:27:32,422 - ERROR - Erro ao criar sessão: name 'pd' is not defined
2024-11-28 14:27:36,292 - ERROR - Erro ao criar sessão: name 'pd' is not defined
2024-11-28 14:27:59,200 - ERROR - Erro ao salvar contagens: [Errno 2] No such file or directory: 'Z:\\\\0Pesquisa\\\\_0ContadorDigital\\\\Contagens\\lucas.melo\\testesalvamento\\testesalvamento_p21_28-11-2024.xlsx'
2024-11-28 14:27:59,201 - ERROR - Erro ao salvar contagens: [Errno 2] No such file or directory: 'Z:\\\\0Pesquisa\\\\_0ContadorDigital\\\\Contagens\\lucas.melo\\testesalvamento\\testesalvamento_p21_28-11-2024.xlsx'
2024-11-28 14:29:00,007 - ERROR - Erro ao salvar contagens: Bad CRC-32 for file 'docProps/core.xml'
2024-11-28 14:29:00,010 - ERROR - Erro ao salvar contagens: Bad CRC-32 for file 'docProps/core.xml'
2024-11-28 14:29:00,484 - ERROR - Erro ao salvar contagens: Bad CRC-32 for file 'docProps/core.xml'
2024-11-28 14:29:00,486 - ERROR - Erro ao salvar contagens: Bad CRC-32 for file 'docProps/core.xml'
2024-11-28 14:29:00,655 - ERROR - Erro ao salvar contagens: Bad CRC-32 for file 'docProps/core.xml'
2024-11-28 14:29:00,655 - ERROR - Erro ao salvar contagens: Bad CRC-32 for file 'docProps/core.xml'
2024-11-28 14:29:16,357 - ERROR - Erro ao salvar contagens: Bad CRC-32 for file 'docProps/core.xml'
2024-11-28 14:29:16,359 - ERROR - Erro ao salvar contagens: Bad CRC-32 for file 'docProps/core.xml'
2024-11-28 14:29:17,526 - ERROR - Erro ao salvar contagens: Bad CRC-32 for file 'docProps/core.xml'
2024-11-28 14:29:17,531 - ERROR - Erro ao salvar contagens: Bad CRC-32 for file 'docProps/core.xml'
2024-11-28 14:29:17,578 - ERROR - Erro ao salvar contagens: Bad CRC-32 for file 'docProps/core.xml'
2024-11-28 14:29:17,578 - ERROR - Erro ao salvar contagens: Bad CRC-32 for file 'docProps/core.xml'
2024-11-28 14:29:19,226 - ERROR - Erro ao salvar contagens: Bad CRC-32 for file 'docProps/core.xml'
2024-11-28 14:29:19,227 - ERROR - Erro ao salvar contagens: Bad CRC-32 for file 'docProps/core.xml'
2024-11-28 15:13:54,894 - ERROR - Erro ao salvar contagens: strptime() argument 1 must be str, not float
2024-11-28 15:13:54,895 - ERROR - Future exception was never retrieved
future: <Future finished exception=TypeError('strptime() argument 1 must be str, not float')>
Traceback (most recent call last):
  File "C:\Users\lucas.melo\AppData\Local\Programs\Python\Python312\Lib\concurrent\futures\thread.py", line 58, in run
    result = self.fn(*self.args, **self.kwargs)
             ^^^^^^^^^^^^^^^^^^^^^^^^^^^^^^^^^^
  File "C:\Users\lucas.melo\traffic-count\venv\Lib\site-packages\flet_core\page.py", line 944, in wrapper
    handler(*args)
  File "C:\Users\lucas.melo\traffic-count\frontend\main.py", line 458, in on_confirm_save
    self._perform_save(now)  # Perform save
    ^^^^^^^^^^^^^^^^^^^^^^^
  File "C:\Users\lucas.melo\traffic-count\frontend\main.py", line 513, in _perform_save
    horario_inicio = datetime.strptime(row['das'], '%H:%M')
                     ^^^^^^^^^^^^^^^^^^^^^^^^^^^^^^^^^^^^^^
TypeError: strptime() argument 1 must be str, not float
2024-11-28 15:14:00,554 - ERROR - Erro ao salvar contagens: strptime() argument 1 must be str, not float
2024-11-28 15:14:00,555 - ERROR - Future exception was never retrieved
future: <Future finished exception=TypeError('strptime() argument 1 must be str, not float')>
Traceback (most recent call last):
  File "C:\Users\lucas.melo\AppData\Local\Programs\Python\Python312\Lib\concurrent\futures\thread.py", line 58, in run
    result = self.fn(*self.args, **self.kwargs)
             ^^^^^^^^^^^^^^^^^^^^^^^^^^^^^^^^^^
  File "C:\Users\lucas.melo\traffic-count\venv\Lib\site-packages\flet_core\page.py", line 944, in wrapper
    handler(*args)
  File "C:\Users\lucas.melo\traffic-count\frontend\main.py", line 458, in on_confirm_save
    self._perform_save(now)  # Perform save
    ^^^^^^^^^^^^^^^^^^^^^^^
  File "C:\Users\lucas.melo\traffic-count\frontend\main.py", line 513, in _perform_save
    horario_inicio = datetime.strptime(row['das'], '%H:%M')
                     ^^^^^^^^^^^^^^^^^^^^^^^^^^^^^^^^^^^^^^
TypeError: strptime() argument 1 must be str, not float
2024-11-28 15:29:07,161 - ERROR - Nenhuma mudança nas contagens desde o último salvamento.
2024-11-28 16:02:23,490 - ERROR - Future exception was never retrieved
future: <Future finished exception=AttributeError("'ContadorPerplan' object has no attribute 'horas_contagem_input'")>
Traceback (most recent call last):
  File "C:\Users\lucas.melo\AppData\Local\Programs\Python\Python312\Lib\concurrent\futures\thread.py", line 58, in run
    result = self.fn(*self.args, **self.kwargs)
             ^^^^^^^^^^^^^^^^^^^^^^^^^^^^^^^^^^
  File "C:\Users\lucas.melo\traffic-count\venv\Lib\site-packages\flet_core\page.py", line 944, in wrapper
    handler(*args)
  File "C:\Users\lucas.melo\traffic-count\frontend\main.py", line 184, in criar_sessao
    sessao.criar_sessao(self, e)
  File "C:\Users\lucas.melo\traffic-count\frontend\app\sessao.py", line 13, in criar_sessao
    if not self.validar_campos():
           ^^^^^^^^^^^^^^^^^^^^^
  File "C:\Users\lucas.melo\traffic-count\frontend\main.py", line 231, in validar_campos
    (self.horas_contagem_input, "Periodo"),
     ^^^^^^^^^^^^^^^^^^^^^^^^^
AttributeError: 'ContadorPerplan' object has no attribute 'horas_contagem_input'
2024-11-28 16:08:59,978 - ERROR - Erro ao criar sessão: ContadorPerplan.gerar_coluna_horarios() takes 1 positional argument but 2 were given
2024-11-28 16:13:23,277 - ERROR - Erro ao criar sessão: ContadorPerplan.gerar_coluna_horarios() missing 1 required positional argument: 'periodo'
2024-11-28 16:19:04,370 - ERROR - Erro ao gerar coluna de horários: time data '24:00' does not match format '%H:%M'
2024-11-28 16:19:08,558 - ERROR - Erro: `horarios_df` não está inicializado ou está vazio.
2024-11-28 16:19:10,536 - ERROR - Erro: `horarios_df` não está inicializado ou está vazio.
2024-11-28 16:19:11,310 - ERROR - Erro: `horarios_df` não está inicializado ou está vazio.
2024-11-28 16:19:11,516 - ERROR - Erro: `horarios_df` não está inicializado ou está vazio.
2024-11-28 16:19:11,894 - ERROR - Erro: `horarios_df` não está inicializado ou está vazio.
2024-11-28 16:19:17,014 - ERROR - Erro: `horarios_df` não está inicializado ou está vazio.
2024-11-28 16:19:34,964 - ERROR - Erro ao gerar coluna de horários: time data '24:00' does not match format '%H:%M'
2024-11-28 16:19:39,497 - ERROR - Erro ao finalizar sessão: [WinError 32] O arquivo já está sendo usado por outro processo: 'C:\\Users\\lucas.melo\\traffic-count\\frontend\\dados.db'
2024-11-28 16:20:03,698 - ERROR - Erro ao gerar coluna de horários: time data '24:00' does not match format '%H:%M'
2024-11-28 16:20:03,950 - ERROR - Erro ao criar sessão: At least one sheet must be visible
2024-11-28 16:37:13,700 - ERROR - Erro ao carregar tokens salvos: ('Leves', 'A')
2024-11-28 16:38:16,081 - ERROR - Erro: `horarios_df` não está inicializado ou está vazio.
2024-11-28 16:43:08,843 - ERROR - Erro ao gerar coluna de horários: time data '24:00' does not match format '%H:%M'
2024-11-28 16:43:12,396 - ERROR - Erro: horarios_df não está inicializado ou está vazio.
2024-11-28 16:59:22,945 - ERROR - Erro ao salvar contagens: [Errno 13] Permission denied: 'Z:\\\\0Pesquisa\\\\_0ContadorDigital\\\\Contagens\\lucas.melo\\ER2402\\ER2402_34_28-11-2024.xlsx'
2024-11-28 16:59:22,946 - ERROR - Erro ao salvar contagens: [Errno 13] Permission denied: 'Z:\\\\0Pesquisa\\\\_0ContadorDigital\\\\Contagens\\lucas.melo\\ER2402\\ER2402_34_28-11-2024.xlsx'
2024-11-28 17:05:20,985 - ERROR - Erro ao finalizar sessão: [WinError 32] O arquivo já está sendo usado por outro processo: 'C:\\Users\\lucas.melo\\traffic-count\\frontend\\dados.db'
2024-11-28 17:26:33,973 - ERROR - Erro ao salvar contagens: O campo de inicio deve ser preenchido.
2024-11-28 17:26:33,973 - ERROR - Erro ao salvar contagens: O campo de inicio deve ser preenchido.
2024-11-28 17:26:36,289 - ERROR - Erro ao finalizar sessão: [WinError 32] O arquivo já está sendo usado por outro processo: 'C:\\Users\\lucas.melo\\traffic-count\\frontend\\dados.db'
2024-11-28 17:26:53,215 - ERROR - Erro ao criar sessão: 'ContadorPerplan' object has no attribute 'fim_input'
2024-11-28 17:27:19,695 - ERROR - Erro ao criar sessão: 'ContadorPerplan' object has no attribute 'fim_input'
2024-11-28 17:29:42,414 - ERROR - Erro ao finalizar sessão: [WinError 32] O arquivo já está sendo usado por outro processo: 'C:\\Users\\lucas.melo\\traffic-count\\frontend\\dados.db'
2024-11-28 17:29:54,906 - ERROR - Erro ao criar sessão: At least one sheet must be visible
2024-11-28 17:30:04,500 - ERROR - Erro ao criar sessão: At least one sheet must be visible
2024-11-28 17:30:42,104 - ERROR - Erro ao carregar tokens salvos: 'ContadorPerplan' object has no attribute 'on_time_selected'
2024-11-28 17:31:12,641 - ERROR - Erro ao carregar tokens salvos: 'ContadorPerplan' object has no attribute 'on_time_selected'
2024-11-28 17:31:38,855 - ERROR - Erro ao carregar tokens salvos: TimePicker.__init__() got an unexpected keyword argument 'label'
2024-11-28 17:31:55,368 - ERROR - Erro ao carregar tokens salvos: TimePicker.__init__() got an unexpected keyword argument 'format_24h'
2024-11-28 17:43:58,142 - ERROR - Erro ao inicializar arquivo Excel: name 'load_workbook' is not defined
2024-11-28 17:43:58,143 - ERROR - Erro ao criar sessão: name 'load_workbook' is not defined
2024-11-28 17:44:19,403 - ERROR - Erro ao salvar contagens: O campo de inicio deve ser preenchido.
2024-11-28 17:44:19,404 - ERROR - Erro ao salvar contagens: O campo de inicio deve ser preenchido.
2024-11-28 17:44:22,579 - ERROR - Erro ao finalizar sessão: [WinError 32] O arquivo já está sendo usado por outro processo: 'C:\\Users\\lucas.melo\\traffic-count\\frontend\\dados.db'
2024-11-28 17:44:43,008 - ERROR - Erro ao inicializar arquivo Excel: name 'load_workbook' is not defined
2024-11-28 17:44:43,009 - ERROR - Erro ao criar sessão: name 'load_workbook' is not defined
2024-11-28 17:45:09,180 - ERROR - Erro ao finalizar sessão: [WinError 32] O arquivo já está sendo usado por outro processo: 'C:\\Users\\lucas.melo\\traffic-count\\frontend\\dados.db'
2024-11-28 17:45:21,176 - ERROR - Erro ao inicializar arquivo Excel: At least one sheet must be visible
2024-11-28 17:45:21,177 - ERROR - Erro ao criar sessão: At least one sheet must be visible
2024-11-28 17:46:36,850 - ERROR - Erro ao finalizar sessão: [WinError 32] O arquivo já está sendo usado por outro processo: 'C:\\Users\\lucas.melo\\traffic-count\\frontend\\dados.db'
2024-11-28 17:46:49,615 - ERROR - Erro ao inicializar arquivo Excel: At least one sheet must be visible
2024-11-28 17:46:49,615 - ERROR - Erro ao criar sessão: At least one sheet must be visible
2024-11-28 17:47:54,307 - ERROR - Erro ao finalizar sessão: [WinError 32] O arquivo já está sendo usado por outro processo: 'C:\\Users\\lucas.melo\\traffic-count\\frontend\\dados.db'
2024-11-28 17:48:05,649 - ERROR - Erro ao inicializar arquivo Excel: Instance '<Categoria at 0x230f3113050>' has been deleted, or its row is otherwise not present.
2024-11-28 17:48:05,650 - ERROR - Erro no banco de dados: Instance '<Categoria at 0x230f3113050>' has been deleted, or its row is otherwise not present.
2024-11-28 17:50:03,355 - ERROR - Erro ao finalizar sessão: [WinError 32] O arquivo já está sendo usado por outro processo: 'C:\\Users\\lucas.melo\\traffic-count\\frontend\\dados.db'
2024-11-28 17:50:12,438 - ERROR - Erro ao inicializar arquivo Excel: At least one sheet must be visible
2024-11-28 17:50:12,439 - ERROR - Erro ao criar sessão: At least one sheet must be visible
2024-11-28 17:51:10,616 - ERROR - Erro ao finalizar sessão: [WinError 32] O arquivo já está sendo usado por outro processo: 'C:\\Users\\lucas.melo\\traffic-count\\frontend\\dados.db'
2024-11-28 17:51:21,992 - ERROR - Erro ao inicializar arquivo Excel: At least one sheet must be visible
2024-11-28 17:51:21,993 - ERROR - Erro ao criar sessão: At least one sheet must be visible
2024-11-28 17:52:16,988 - ERROR - Erro ao inicializar arquivo Excel: Cannot convert ['A', 'B'] to Excel
2024-11-28 17:52:16,990 - ERROR - Erro ao criar sessão: Cannot convert ['A', 'B'] to Excel
2024-11-28 17:53:41,519 - ERROR - Erro ao finalizar sessão: [WinError 32] O arquivo já está sendo usado por outro processo: 'C:\\Users\\lucas.melo\\traffic-count\\frontend\\dados.db'
2024-11-28 22:54:39,790 - ERROR - Nenhuma mudança nas contagens desde o último salvamento.
2024-11-28 22:54:56,550 - ERROR - Erro ao salvar contagens: O campo de inicio deve ser preenchido.
2024-11-28 22:54:56,551 - ERROR - Erro ao salvar contagens: O campo de inicio deve ser preenchido.
2024-11-28 22:55:02,652 - ERROR - Erro ao finalizar sessão: [WinError 32] O arquivo já está sendo usado por outro processo: 'C:\\Users\\lucas.melo\\traffic-count\\frontend\\dados.db'
2024-11-28 22:59:38,380 - ERROR - Erro ao finalizar sessão: [WinError 32] O arquivo já está sendo usado por outro processo: 'C:\\Users\\lucas.melo\\traffic-count\\frontend\\dados.db'
2024-12-02 15:50:10,727 - ERROR - Erro ao salvar contagens: O campo de inicio deve ser preenchido.
2024-12-02 15:50:10,732 - ERROR - Erro ao salvar contagens: O campo de inicio deve ser preenchido.
2024-12-11 14:44:35,613 - ERROR - Erro ao salvar contagens: O campo de inicio deve ser preenchido.
2024-12-11 14:44:35,615 - ERROR - Erro ao salvar contagens: O campo de inicio deve ser preenchido.
2024-12-11 15:37:35,352 - ERROR - Future exception was never retrieved
future: <Future finished exception=NameError("name 'formatar_period' is not defined")>
Traceback (most recent call last):
  File "C:\Users\lucas.melo\AppData\Local\Programs\Python\Python312\Lib\concurrent\futures\thread.py", line 58, in run
    result = self.fn(*self.args, **self.kwargs)
             ^^^^^^^^^^^^^^^^^^^^^^^^^^^^^^^^^^
  File "C:\Users\lucas.melo\traffic-count\venv\Lib\site-packages\flet_core\page.py", line 944, in wrapper
    handler(*args)
  File "C:\Users\lucas.melo\traffic-count\frontend\main.py", line 165, in criar_sessao
    sessao.criar_sessao(self, e)
  File "C:\Users\lucas.melo\traffic-count\frontend\app\sessao.py", line 16, in criar_sessao
    if not self.validar_campos():
           ^^^^^^^^^^^^^^^^^^^^^
  File "C:\Users\lucas.melo\traffic-count\frontend\main.py", line 279, in validar_campos
    period = formatar_period(self.inicio_input.value, "23:59")
             ^^^^^^^^^^^^^^^
NameError: name 'formatar_period' is not defined. Did you mean: 'format_period'?
2024-12-11 15:38:36,624 - ERROR - Erro ao criar sessão: 'details' is an invalid keyword argument for Sessao
2024-12-11 15:39:55,142 - ERROR - Erro inesperado ao carregar categorias: 'ContadorPerplan' object has no attribute 'details'
2024-12-11 15:39:55,144 - ERROR - Erro ao carregar padrões: Erro ao carregar categorias: 'ContadorPerplan' object has no attribute 'details'
2024-12-11 15:53:01,027 - ERROR - Erro ao inicializar arquivo Excel: 'ContadorPerplan' object has no attribute 'horarios_df'
2024-12-11 15:53:01,029 - ERROR - Erro ao criar sessão: 'ContadorPerplan' object has no attribute 'horarios_df'
2024-12-11 16:20:18,501 - ERROR - Erro ao gerar coluna de horários: time data '' does not match format '%H:%M'
2024-12-11 16:20:20,138 - ERROR - Erro: horarios_df não está inicializado ou está vazio.
2024-12-11 18:54:23,478 - ERROR - Erro ao gerar coluna de horários: time data '' does not match format '%H:%M'
2024-12-11 19:20:24,195 - ERROR - Erro ao carregar sessão ativa: 'ContadorPerplan' object has no attribute 'gerar_coluna_horarios'
2024-12-11 19:21:36,854 - ERROR - Erro ao inicializar arquivo Excel: 'ContadorPerplan' object has no attribute 'horarios_df'
2024-12-11 19:21:36,855 - ERROR - Erro ao criar sessão: 'ContadorPerplan' object has no attribute 'horarios_df'
2024-12-11 19:22:59,954 - ERROR - Erro ao inicializar arquivo Excel: name 'df_horarios' is not defined
2024-12-11 19:22:59,955 - ERROR - Erro ao criar sessão: name 'df_horarios' is not defined
2024-12-11 19:29:44,395 - ERROR - Erro: horarios_df não está inicializado ou está vazio.
2024-12-11 19:29:55,130 - ERROR - Erro: horarios_df não está inicializado ou está vazio.
2024-12-11 19:55:15,070 - ERROR - Erro ao salvar contagens: time data '' does not match format '%H:%M'
2024-12-11 19:55:15,072 - ERROR - Erro ao salvar contagens: time data '' does not match format '%H:%M'
2024-12-11 20:16:21,645 - ERROR - Erro ao carregar sessão ativa: 'Periodo'
2024-12-11 20:25:09,938 - ERROR - Erro ao salvar contagens: This session is in 'prepared' state; no further SQL can be emitted within this transaction.
2024-12-11 20:25:09,940 - ERROR - Future exception was never retrieved
future: <Future finished exception=InvalidRequestError("This session is in 'prepared' state; no further SQL can be emitted within this transaction.")>
Traceback (most recent call last):
  File "C:\Users\lucas.melo\AppData\Local\Programs\Python\Python312\Lib\concurrent\futures\thread.py", line 58, in run
    result = self.fn(*self.args, **self.kwargs)
             ^^^^^^^^^^^^^^^^^^^^^^^^^^^^^^^^^^
  File "C:\Users\lucas.melo\traffic-count\venv\Lib\site-packages\flet_core\page.py", line 944, in wrapper
    handler(*args)
  File "C:\Users\lucas.melo\traffic-count\frontend\main.py", line 452, in on_confirm_save
    self._perform_save(now)
  File "C:\Users\lucas.melo\traffic-count\frontend\main.py", line 508, in _perform_save
    for categoria in [c for c in self.categorias if c.movimento == movimento]:
                                                    ^^^^^^^^^^^
  File "C:\Users\lucas.melo\traffic-count\venv\Lib\site-packages\sqlalchemy\orm\attributes.py", line 566, in __get__
    return self.impl.get(state, dict_)  # type: ignore[no-any-return]
           ^^^^^^^^^^^^^^^^^^^^^^^^^^^
  File "C:\Users\lucas.melo\traffic-count\venv\Lib\site-packages\sqlalchemy\orm\attributes.py", line 1086, in get
    value = self._fire_loader_callables(state, key, passive)
            ^^^^^^^^^^^^^^^^^^^^^^^^^^^^^^^^^^^^^^^^^^^^^^^^
  File "C:\Users\lucas.melo\traffic-count\venv\Lib\site-packages\sqlalchemy\orm\attributes.py", line 1116, in _fire_loader_callables
    return state._load_expired(state, passive)
           ^^^^^^^^^^^^^^^^^^^^^^^^^^^^^^^^^^^
  File "C:\Users\lucas.melo\traffic-count\venv\Lib\site-packages\sqlalchemy\orm\state.py", line 803, in _load_expired
    self.manager.expired_attribute_loader(self, toload, passive)
  File "C:\Users\lucas.melo\traffic-count\venv\Lib\site-packages\sqlalchemy\orm\loading.py", line 1670, in load_scalar_attributes
    result = load_on_ident(
             ^^^^^^^^^^^^^^
  File "C:\Users\lucas.melo\traffic-count\venv\Lib\site-packages\sqlalchemy\orm\loading.py", line 509, in load_on_ident
    return load_on_pk_identity(
           ^^^^^^^^^^^^^^^^^^^^
  File "C:\Users\lucas.melo\traffic-count\venv\Lib\site-packages\sqlalchemy\orm\loading.py", line 694, in load_on_pk_identity
    session.execute(
  File "C:\Users\lucas.melo\traffic-count\venv\Lib\site-packages\sqlalchemy\orm\session.py", line 2362, in execute
    return self._execute_internal(
           ^^^^^^^^^^^^^^^^^^^^^^^
  File "C:\Users\lucas.melo\traffic-count\venv\Lib\site-packages\sqlalchemy\orm\session.py", line 2237, in _execute_internal
    conn = self._connection_for_bind(bind)
           ^^^^^^^^^^^^^^^^^^^^^^^^^^^^^^^
  File "C:\Users\lucas.melo\traffic-count\venv\Lib\site-packages\sqlalchemy\orm\session.py", line 2106, in _connection_for_bind
    return trans._connection_for_bind(engine, execution_options)
           ^^^^^^^^^^^^^^^^^^^^^^^^^^^^^^^^^^^^^^^^^^^^^^^^^^^^^
  File "<string>", line 2, in _connection_for_bind
  File "C:\Users\lucas.melo\traffic-count\venv\Lib\site-packages\sqlalchemy\orm\state_changes.py", line 103, in _go
    self._raise_for_prerequisite_state(fn.__name__, current_state)
  File "C:\Users\lucas.melo\traffic-count\venv\Lib\site-packages\sqlalchemy\orm\session.py", line 996, in _raise_for_prerequisite_state
    raise sa_exc.InvalidRequestError(
sqlalchemy.exc.InvalidRequestError: This session is in 'prepared' state; no further SQL can be emitted within this transaction.
2024-12-13 14:08:13,016 - ERROR - Erro ao carregar tokens salvos: DatePicker.__init__() got an unexpected keyword argument 'locale'
2024-12-13 14:26:36,724 - ERROR - Erro ao carregar tokens salvos: 'ContadorPerplan' object has no attribute 'on_date_confirmed'
2024-12-13 14:30:57,342 - ERROR - Future exception was never retrieved
future: <Future finished exception=ValueError('list.remove(x): x not in list')>
Traceback (most recent call last):
  File "C:\Users\lucas.melo\AppData\Local\Programs\Python\Python312\Lib\concurrent\futures\thread.py", line 58, in run
    result = self.fn(*self.args, **self.kwargs)
             ^^^^^^^^^^^^^^^^^^^^^^^^^^^^^^^^^^
  File "C:\Users\lucas.melo\traffic-count\venv\Lib\site-packages\flet_core\page.py", line 944, in wrapper
    handler(*args)
  File "C:\Users\lucas.melo\traffic-count\frontend\utils\datepicker.py", line 77, in cancel_selection
    self.on_cancel()
  File "C:\Users\lucas.melo\traffic-count\frontend\main.py", line 67, in on_date_cancelled
    self.page.controls.remove(self.custom_date_picker)
ValueError: list.remove(x): x not in list
2024-12-13 14:30:57,603 - ERROR - Future exception was never retrieved
future: <Future finished exception=ValueError('list.remove(x): x not in list')>
Traceback (most recent call last):
  File "C:\Users\lucas.melo\AppData\Local\Programs\Python\Python312\Lib\concurrent\futures\thread.py", line 58, in run
    result = self.fn(*self.args, **self.kwargs)
             ^^^^^^^^^^^^^^^^^^^^^^^^^^^^^^^^^^
  File "C:\Users\lucas.melo\traffic-count\venv\Lib\site-packages\flet_core\page.py", line 944, in wrapper
    handler(*args)
  File "C:\Users\lucas.melo\traffic-count\frontend\utils\datepicker.py", line 77, in cancel_selection
    self.on_cancel()
  File "C:\Users\lucas.melo\traffic-count\frontend\main.py", line 67, in on_date_cancelled
    self.page.controls.remove(self.custom_date_picker)
ValueError: list.remove(x): x not in list
2024-12-13 14:44:50,880 - ERROR - Future exception was never retrieved
future: <Future finished exception=ValueError('list.remove(x): x not in list')>
Traceback (most recent call last):
  File "C:\Users\lucas.melo\AppData\Local\Programs\Python\Python312\Lib\concurrent\futures\thread.py", line 58, in run
    result = self.fn(*self.args, **self.kwargs)
             ^^^^^^^^^^^^^^^^^^^^^^^^^^^^^^^^^^
  File "C:\Users\lucas.melo\traffic-count\venv\Lib\site-packages\flet_core\page.py", line 944, in wrapper
    handler(*args)
  File "C:\Users\lucas.melo\traffic-count\frontend\utils\datepicker.py", line 89, in cancel_selection
    self.on_cancel()
  File "C:\Users\lucas.melo\traffic-count\frontend\main.py", line 67, in on_date_cancelled
    self.page.controls.remove(self.custom_date_picker)
ValueError: list.remove(x): x not in list
2024-12-13 14:44:52,097 - ERROR - Future exception was never retrieved
future: <Future finished exception=ValueError('list.remove(x): x not in list')>
Traceback (most recent call last):
  File "C:\Users\lucas.melo\AppData\Local\Programs\Python\Python312\Lib\concurrent\futures\thread.py", line 58, in run
    result = self.fn(*self.args, **self.kwargs)
             ^^^^^^^^^^^^^^^^^^^^^^^^^^^^^^^^^^
  File "C:\Users\lucas.melo\traffic-count\venv\Lib\site-packages\flet_core\page.py", line 944, in wrapper
    handler(*args)
  File "C:\Users\lucas.melo\traffic-count\frontend\utils\datepicker.py", line 89, in cancel_selection
    self.on_cancel()
  File "C:\Users\lucas.melo\traffic-count\frontend\main.py", line 67, in on_date_cancelled
    self.page.controls.remove(self.custom_date_picker)
ValueError: list.remove(x): x not in list
2024-12-13 14:44:52,292 - ERROR - Future exception was never retrieved
future: <Future finished exception=ValueError('list.remove(x): x not in list')>
Traceback (most recent call last):
  File "C:\Users\lucas.melo\AppData\Local\Programs\Python\Python312\Lib\concurrent\futures\thread.py", line 58, in run
    result = self.fn(*self.args, **self.kwargs)
             ^^^^^^^^^^^^^^^^^^^^^^^^^^^^^^^^^^
  File "C:\Users\lucas.melo\traffic-count\venv\Lib\site-packages\flet_core\page.py", line 944, in wrapper
    handler(*args)
  File "C:\Users\lucas.melo\traffic-count\frontend\utils\datepicker.py", line 89, in cancel_selection
    self.on_cancel()
  File "C:\Users\lucas.melo\traffic-count\frontend\main.py", line 67, in on_date_cancelled
    self.page.controls.remove(self.custom_date_picker)
ValueError: list.remove(x): x not in list
2024-12-13 14:54:40,062 - ERROR - Future exception was never retrieved
future: <Future finished exception=AttributeError("'ContadorPerplan' object has no attribute 'data_ponto_label'")>
Traceback (most recent call last):
  File "C:\Users\lucas.melo\AppData\Local\Programs\Python\Python312\Lib\concurrent\futures\thread.py", line 58, in run
    result = self.fn(*self.args, **self.kwargs)
             ^^^^^^^^^^^^^^^^^^^^^^^^^^^^^^^^^^
  File "C:\Users\lucas.melo\traffic-count\venv\Lib\site-packages\flet_core\page.py", line 944, in wrapper
    handler(*args)
  File "C:\Users\lucas.melo\traffic-count\frontend\main.py", line 119, in criar_sessao
    sessao.criar_sessao(self, e)
  File "C:\Users\lucas.melo\traffic-count\frontend\app\sessao.py", line 16, in criar_sessao
    if not self.validar_campos():
           ^^^^^^^^^^^^^^^^^^^^^
  File "C:\Users\lucas.melo\traffic-count\frontend\main.py", line 187, in validar_campos
    (self.data_ponto_label, "Data do Ponto")
     ^^^^^^^^^^^^^^^^^^^^^
AttributeError: 'ContadorPerplan' object has no attribute 'data_ponto_label'. Did you mean: 'data_ponto_input'?
2024-12-13 14:59:27,159 - ERROR - Erro ao criar sessão: 'ContadorPerplan' object has no attribute 'data_ponto_label'
2024-12-13 15:00:46,459 - ERROR - Erro ao inicializar arquivo Excel: [Errno 22] Invalid argument: 'Z:\\\\0Pesquisa\\\\_0ContadorDigital\\\\Contagens\\lucas.melo\\Teste\\Teste_P10_13-12-2024_06:15 - 23:59.xlsx'
2024-12-13 15:00:46,461 - ERROR - Erro ao criar sessão: [Errno 22] Invalid argument: 'Z:\\\\0Pesquisa\\\\_0ContadorDigital\\\\Contagens\\lucas.melo\\Teste\\Teste_P10_13-12-2024_06:15 - 23:59.xlsx'
2024-12-13 15:01:30,870 - ERROR - Erro ao criar sessão: format_period() missing 1 required positional argument: 'end_date'
2024-12-13 15:03:08,404 - ERROR - Erro ao inicializar arquivo Excel: [Errno 22] Invalid argument: 'Z:\\\\0Pesquisa\\\\_0ContadorDigital\\\\Contagens\\lucas.melo\\teste\\teste_p10_13-12-2024_06:30 - 23:59.xlsx'
2024-12-13 15:03:08,405 - ERROR - Erro ao criar sessão: [Errno 22] Invalid argument: 'Z:\\\\0Pesquisa\\\\_0ContadorDigital\\\\Contagens\\lucas.melo\\teste\\teste_p10_13-12-2024_06:30 - 23:59.xlsx'
2024-12-16 16:19:03,068 - ERROR - Erro ao carregar tokens salvos: 'str' object has no attribute '_build_add_commands'
2024-12-17 15:52:04,380 - ERROR - Erro ao carregar tokens salvos: TimePicker.__init__() got an unexpected keyword argument 'show_seconds'
2024-12-17 15:54:26,897 - ERROR - Erro ao carregar tokens salvos: TimePicker.__init__() got an unexpected keyword argument 'hour_format'
2024-12-17 15:54:58,803 - ERROR - Future exception was never retrieved
future: <Future finished exception=AttributeError("'datetime.time' object has no attribute 'split'")>
Traceback (most recent call last):
  File "C:\Users\lucas.melo\AppData\Local\Programs\Python\Python312\Lib\concurrent\futures\thread.py", line 58, in run
    result = self.fn(*self.args, **self.kwargs)
             ^^^^^^^^^^^^^^^^^^^^^^^^^^^^^^^^^^
  File "C:\Users\lucas.melo\traffic-count\venv\Lib\site-packages\flet_core\page.py", line 944, in wrapper
    handler(*args)
  File "C:\Users\lucas.melo\traffic-count\frontend\main.py", line 130, in period_changed
    hours, minutes = map(int, selected_time.split(":"))
                              ^^^^^^^^^^^^^^^^^^^
AttributeError: 'datetime.time' object has no attribute 'split'
2024-12-17 15:55:12,964 - ERROR - Future exception was never retrieved
future: <Future finished exception=AttributeError("'datetime.time' object has no attribute 'split'")>
Traceback (most recent call last):
  File "C:\Users\lucas.melo\AppData\Local\Programs\Python\Python312\Lib\concurrent\futures\thread.py", line 58, in run
    result = self.fn(*self.args, **self.kwargs)
             ^^^^^^^^^^^^^^^^^^^^^^^^^^^^^^^^^^
  File "C:\Users\lucas.melo\traffic-count\venv\Lib\site-packages\flet_core\page.py", line 944, in wrapper
    handler(*args)
  File "C:\Users\lucas.melo\traffic-count\frontend\main.py", line 130, in period_changed
    hours, minutes = map(int, selected_time.split(":"))
                              ^^^^^^^^^^^^^^^^^^^
AttributeError: 'datetime.time' object has no attribute 'split'
2024-12-17 15:57:09,494 - ERROR - Future exception was never retrieved
future: <Future finished exception=AttributeError("'datetime.time' object has no attribute 'split'")>
Traceback (most recent call last):
  File "C:\Users\lucas.melo\AppData\Local\Programs\Python\Python312\Lib\concurrent\futures\thread.py", line 58, in run
    result = self.fn(*self.args, **self.kwargs)
             ^^^^^^^^^^^^^^^^^^^^^^^^^^^^^^^^^^
  File "C:\Users\lucas.melo\traffic-count\venv\Lib\site-packages\flet_core\page.py", line 944, in wrapper
    handler(*args)
  File "C:\Users\lucas.melo\traffic-count\frontend\main.py", line 130, in period_changed
    hours, minutes = map(int, selected_time.split(":"))
                              ^^^^^^^^^^^^^^^^^^^
AttributeError: 'datetime.time' object has no attribute 'split'
2024-12-17 15:57:53,036 - ERROR - Future exception was never retrieved
future: <Future finished exception=TypeError("descriptor 'time' for 'datetime.datetime' objects doesn't apply to a 'int' object")>
Traceback (most recent call last):
  File "C:\Users\lucas.melo\AppData\Local\Programs\Python\Python312\Lib\concurrent\futures\thread.py", line 58, in run
    result = self.fn(*self.args, **self.kwargs)
             ^^^^^^^^^^^^^^^^^^^^^^^^^^^^^^^^^^
  File "C:\Users\lucas.melo\traffic-count\venv\Lib\site-packages\flet_core\page.py", line 944, in wrapper
    handler(*args)
  File "C:\Users\lucas.melo\traffic-count\frontend\main.py", line 134, in period_changed
    self.period_picker.value = datetime.time(hours, adjusted_minutes)
                               ^^^^^^^^^^^^^^^^^^^^^^^^^^^^^^^^^^^^^^
TypeError: descriptor 'time' for 'datetime.datetime' objects doesn't apply to a 'int' object
2024-12-17 16:15:50,592 - ERROR - Erro ao carregar tokens salvos: module 'flet' has no attribute 'CupertinoTimePicker'
2024-12-17 16:21:35,141 - ERROR - Erro ao carregar tokens salvos: module 'flet' has no attribute 'CupertinoTimePicker'
2024-12-17 16:26:41,436 - ERROR - Future exception was never retrieved
future: <Future finished exception=AttributeError("'int' object has no attribute 'minute'")>
Traceback (most recent call last):
  File "C:\Users\lucas.melo\AppData\Local\Programs\Python\Python312\Lib\concurrent\futures\thread.py", line 58, in run
    result = self.fn(*self.args, **self.kwargs)
             ^^^^^^^^^^^^^^^^^^^^^^^^^^^^^^^^^^
  File "C:\Users\lucas.melo\traffic-count\venv\Lib\site-packages\flet_core\page.py", line 944, in wrapper
    handler(*args)
  File "C:\Users\lucas.melo\traffic-count\frontend\main.py", line 82, in picker_changed
    adjusted_minutes = (selected.minute // 15) * 15
                        ^^^^^^^^^^^^^^^
AttributeError: 'int' object has no attribute 'minute'
2024-12-17 16:26:41,609 - ERROR - Future exception was never retrieved
future: <Future finished exception=AttributeError("'int' object has no attribute 'minute'")>
Traceback (most recent call last):
  File "C:\Users\lucas.melo\AppData\Local\Programs\Python\Python312\Lib\concurrent\futures\thread.py", line 58, in run
    result = self.fn(*self.args, **self.kwargs)
             ^^^^^^^^^^^^^^^^^^^^^^^^^^^^^^^^^^
  File "C:\Users\lucas.melo\traffic-count\venv\Lib\site-packages\flet_core\page.py", line 944, in wrapper
    handler(*args)
  File "C:\Users\lucas.melo\traffic-count\frontend\main.py", line 82, in picker_changed
    adjusted_minutes = (selected.minute // 15) * 15
                        ^^^^^^^^^^^^^^^
AttributeError: 'int' object has no attribute 'minute'
2024-12-17 16:26:42,178 - ERROR - Future exception was never retrieved
future: <Future finished exception=AttributeError("'int' object has no attribute 'minute'")>
Traceback (most recent call last):
  File "C:\Users\lucas.melo\AppData\Local\Programs\Python\Python312\Lib\concurrent\futures\thread.py", line 58, in run
    result = self.fn(*self.args, **self.kwargs)
             ^^^^^^^^^^^^^^^^^^^^^^^^^^^^^^^^^^
  File "C:\Users\lucas.melo\traffic-count\venv\Lib\site-packages\flet_core\page.py", line 944, in wrapper
    handler(*args)
  File "C:\Users\lucas.melo\traffic-count\frontend\main.py", line 82, in picker_changed
    adjusted_minutes = (selected.minute // 15) * 15
                        ^^^^^^^^^^^^^^^
AttributeError: 'int' object has no attribute 'minute'
2024-12-17 16:26:42,306 - ERROR - Future exception was never retrieved
future: <Future finished exception=AttributeError("'int' object has no attribute 'minute'")>
Traceback (most recent call last):
  File "C:\Users\lucas.melo\AppData\Local\Programs\Python\Python312\Lib\concurrent\futures\thread.py", line 58, in run
    result = self.fn(*self.args, **self.kwargs)
             ^^^^^^^^^^^^^^^^^^^^^^^^^^^^^^^^^^
  File "C:\Users\lucas.melo\traffic-count\venv\Lib\site-packages\flet_core\page.py", line 944, in wrapper
    handler(*args)
  File "C:\Users\lucas.melo\traffic-count\frontend\main.py", line 82, in picker_changed
    adjusted_minutes = (selected.minute // 15) * 15
                        ^^^^^^^^^^^^^^^
AttributeError: 'int' object has no attribute 'minute'
2024-12-17 16:26:42,423 - ERROR - Future exception was never retrieved
future: <Future finished exception=AttributeError("'int' object has no attribute 'minute'")>
Traceback (most recent call last):
  File "C:\Users\lucas.melo\AppData\Local\Programs\Python\Python312\Lib\concurrent\futures\thread.py", line 58, in run
    result = self.fn(*self.args, **self.kwargs)
             ^^^^^^^^^^^^^^^^^^^^^^^^^^^^^^^^^^
  File "C:\Users\lucas.melo\traffic-count\venv\Lib\site-packages\flet_core\page.py", line 944, in wrapper
    handler(*args)
  File "C:\Users\lucas.melo\traffic-count\frontend\main.py", line 82, in picker_changed
    adjusted_minutes = (selected.minute // 15) * 15
                        ^^^^^^^^^^^^^^^
AttributeError: 'int' object has no attribute 'minute'
2024-12-17 16:26:42,473 - ERROR - Future exception was never retrieved
future: <Future finished exception=AttributeError("'int' object has no attribute 'minute'")>
Traceback (most recent call last):
  File "C:\Users\lucas.melo\AppData\Local\Programs\Python\Python312\Lib\concurrent\futures\thread.py", line 58, in run
    result = self.fn(*self.args, **self.kwargs)
             ^^^^^^^^^^^^^^^^^^^^^^^^^^^^^^^^^^
  File "C:\Users\lucas.melo\traffic-count\venv\Lib\site-packages\flet_core\page.py", line 944, in wrapper
    handler(*args)
  File "C:\Users\lucas.melo\traffic-count\frontend\main.py", line 82, in picker_changed
    adjusted_minutes = (selected.minute // 15) * 15
                        ^^^^^^^^^^^^^^^
AttributeError: 'int' object has no attribute 'minute'
2024-12-17 16:26:42,627 - ERROR - Future exception was never retrieved
future: <Future finished exception=AttributeError("'int' object has no attribute 'minute'")>
Traceback (most recent call last):
  File "C:\Users\lucas.melo\AppData\Local\Programs\Python\Python312\Lib\concurrent\futures\thread.py", line 58, in run
    result = self.fn(*self.args, **self.kwargs)
             ^^^^^^^^^^^^^^^^^^^^^^^^^^^^^^^^^^
  File "C:\Users\lucas.melo\traffic-count\venv\Lib\site-packages\flet_core\page.py", line 944, in wrapper
    handler(*args)
  File "C:\Users\lucas.melo\traffic-count\frontend\main.py", line 82, in picker_changed
    adjusted_minutes = (selected.minute // 15) * 15
                        ^^^^^^^^^^^^^^^
AttributeError: 'int' object has no attribute 'minute'
2024-12-17 16:26:42,665 - ERROR - Future exception was never retrieved
future: <Future finished exception=AttributeError("'int' object has no attribute 'minute'")>
Traceback (most recent call last):
  File "C:\Users\lucas.melo\AppData\Local\Programs\Python\Python312\Lib\concurrent\futures\thread.py", line 58, in run
    result = self.fn(*self.args, **self.kwargs)
             ^^^^^^^^^^^^^^^^^^^^^^^^^^^^^^^^^^
  File "C:\Users\lucas.melo\traffic-count\venv\Lib\site-packages\flet_core\page.py", line 944, in wrapper
    handler(*args)
  File "C:\Users\lucas.melo\traffic-count\frontend\main.py", line 82, in picker_changed
    adjusted_minutes = (selected.minute // 15) * 15
                        ^^^^^^^^^^^^^^^
AttributeError: 'int' object has no attribute 'minute'
2024-12-17 16:26:42,722 - ERROR - Future exception was never retrieved
future: <Future finished exception=AttributeError("'int' object has no attribute 'minute'")>
Traceback (most recent call last):
  File "C:\Users\lucas.melo\AppData\Local\Programs\Python\Python312\Lib\concurrent\futures\thread.py", line 58, in run
    result = self.fn(*self.args, **self.kwargs)
             ^^^^^^^^^^^^^^^^^^^^^^^^^^^^^^^^^^
  File "C:\Users\lucas.melo\traffic-count\venv\Lib\site-packages\flet_core\page.py", line 944, in wrapper
    handler(*args)
  File "C:\Users\lucas.melo\traffic-count\frontend\main.py", line 82, in picker_changed
    adjusted_minutes = (selected.minute // 15) * 15
                        ^^^^^^^^^^^^^^^
AttributeError: 'int' object has no attribute 'minute'
2024-12-17 16:26:42,767 - ERROR - Future exception was never retrieved
future: <Future finished exception=AttributeError("'int' object has no attribute 'minute'")>
Traceback (most recent call last):
  File "C:\Users\lucas.melo\AppData\Local\Programs\Python\Python312\Lib\concurrent\futures\thread.py", line 58, in run
    result = self.fn(*self.args, **self.kwargs)
             ^^^^^^^^^^^^^^^^^^^^^^^^^^^^^^^^^^
  File "C:\Users\lucas.melo\traffic-count\venv\Lib\site-packages\flet_core\page.py", line 944, in wrapper
    handler(*args)
  File "C:\Users\lucas.melo\traffic-count\frontend\main.py", line 82, in picker_changed
    adjusted_minutes = (selected.minute // 15) * 15
                        ^^^^^^^^^^^^^^^
AttributeError: 'int' object has no attribute 'minute'
2024-12-17 16:26:42,833 - ERROR - Future exception was never retrieved
future: <Future finished exception=AttributeError("'int' object has no attribute 'minute'")>
Traceback (most recent call last):
  File "C:\Users\lucas.melo\AppData\Local\Programs\Python\Python312\Lib\concurrent\futures\thread.py", line 58, in run
    result = self.fn(*self.args, **self.kwargs)
             ^^^^^^^^^^^^^^^^^^^^^^^^^^^^^^^^^^
  File "C:\Users\lucas.melo\traffic-count\venv\Lib\site-packages\flet_core\page.py", line 944, in wrapper
    handler(*args)
  File "C:\Users\lucas.melo\traffic-count\frontend\main.py", line 82, in picker_changed
    adjusted_minutes = (selected.minute // 15) * 15
                        ^^^^^^^^^^^^^^^
AttributeError: 'int' object has no attribute 'minute'
2024-12-17 16:26:43,586 - ERROR - Future exception was never retrieved
future: <Future finished exception=AttributeError("'int' object has no attribute 'minute'")>
Traceback (most recent call last):
  File "C:\Users\lucas.melo\AppData\Local\Programs\Python\Python312\Lib\concurrent\futures\thread.py", line 58, in run
    result = self.fn(*self.args, **self.kwargs)
             ^^^^^^^^^^^^^^^^^^^^^^^^^^^^^^^^^^
  File "C:\Users\lucas.melo\traffic-count\venv\Lib\site-packages\flet_core\page.py", line 944, in wrapper
    handler(*args)
  File "C:\Users\lucas.melo\traffic-count\frontend\main.py", line 82, in picker_changed
    adjusted_minutes = (selected.minute // 15) * 15
                        ^^^^^^^^^^^^^^^
AttributeError: 'int' object has no attribute 'minute'
2024-12-17 16:26:43,695 - ERROR - Future exception was never retrieved
future: <Future finished exception=AttributeError("'int' object has no attribute 'minute'")>
Traceback (most recent call last):
  File "C:\Users\lucas.melo\AppData\Local\Programs\Python\Python312\Lib\concurrent\futures\thread.py", line 58, in run
    result = self.fn(*self.args, **self.kwargs)
             ^^^^^^^^^^^^^^^^^^^^^^^^^^^^^^^^^^
  File "C:\Users\lucas.melo\traffic-count\venv\Lib\site-packages\flet_core\page.py", line 944, in wrapper
    handler(*args)
  File "C:\Users\lucas.melo\traffic-count\frontend\main.py", line 82, in picker_changed
    adjusted_minutes = (selected.minute // 15) * 15
                        ^^^^^^^^^^^^^^^
AttributeError: 'int' object has no attribute 'minute'
2024-12-17 16:26:43,822 - ERROR - Future exception was never retrieved
future: <Future finished exception=AttributeError("'int' object has no attribute 'minute'")>
Traceback (most recent call last):
  File "C:\Users\lucas.melo\AppData\Local\Programs\Python\Python312\Lib\concurrent\futures\thread.py", line 58, in run
    result = self.fn(*self.args, **self.kwargs)
             ^^^^^^^^^^^^^^^^^^^^^^^^^^^^^^^^^^
  File "C:\Users\lucas.melo\traffic-count\venv\Lib\site-packages\flet_core\page.py", line 944, in wrapper
    handler(*args)
  File "C:\Users\lucas.melo\traffic-count\frontend\main.py", line 82, in picker_changed
    adjusted_minutes = (selected.minute // 15) * 15
                        ^^^^^^^^^^^^^^^
AttributeError: 'int' object has no attribute 'minute'
2024-12-17 16:26:43,956 - ERROR - Future exception was never retrieved
future: <Future finished exception=AttributeError("'int' object has no attribute 'minute'")>
Traceback (most recent call last):
  File "C:\Users\lucas.melo\AppData\Local\Programs\Python\Python312\Lib\concurrent\futures\thread.py", line 58, in run
    result = self.fn(*self.args, **self.kwargs)
             ^^^^^^^^^^^^^^^^^^^^^^^^^^^^^^^^^^
  File "C:\Users\lucas.melo\traffic-count\venv\Lib\site-packages\flet_core\page.py", line 944, in wrapper
    handler(*args)
  File "C:\Users\lucas.melo\traffic-count\frontend\main.py", line 82, in picker_changed
    adjusted_minutes = (selected.minute // 15) * 15
                        ^^^^^^^^^^^^^^^
AttributeError: 'int' object has no attribute 'minute'
2024-12-17 16:26:44,048 - ERROR - Future exception was never retrieved
future: <Future finished exception=AttributeError("'int' object has no attribute 'minute'")>
Traceback (most recent call last):
  File "C:\Users\lucas.melo\AppData\Local\Programs\Python\Python312\Lib\concurrent\futures\thread.py", line 58, in run
    result = self.fn(*self.args, **self.kwargs)
             ^^^^^^^^^^^^^^^^^^^^^^^^^^^^^^^^^^
  File "C:\Users\lucas.melo\traffic-count\venv\Lib\site-packages\flet_core\page.py", line 944, in wrapper
    handler(*args)
  File "C:\Users\lucas.melo\traffic-count\frontend\main.py", line 82, in picker_changed
    adjusted_minutes = (selected.minute // 15) * 15
                        ^^^^^^^^^^^^^^^
AttributeError: 'int' object has no attribute 'minute'
2024-12-17 16:26:44,228 - ERROR - Future exception was never retrieved
future: <Future finished exception=AttributeError("'int' object has no attribute 'minute'")>
Traceback (most recent call last):
  File "C:\Users\lucas.melo\AppData\Local\Programs\Python\Python312\Lib\concurrent\futures\thread.py", line 58, in run
    result = self.fn(*self.args, **self.kwargs)
             ^^^^^^^^^^^^^^^^^^^^^^^^^^^^^^^^^^
  File "C:\Users\lucas.melo\traffic-count\venv\Lib\site-packages\flet_core\page.py", line 944, in wrapper
    handler(*args)
  File "C:\Users\lucas.melo\traffic-count\frontend\main.py", line 82, in picker_changed
    adjusted_minutes = (selected.minute // 15) * 15
                        ^^^^^^^^^^^^^^^
AttributeError: 'int' object has no attribute 'minute'
2024-12-17 16:26:44,265 - ERROR - Future exception was never retrieved
future: <Future finished exception=AttributeError("'int' object has no attribute 'minute'")>
Traceback (most recent call last):
  File "C:\Users\lucas.melo\AppData\Local\Programs\Python\Python312\Lib\concurrent\futures\thread.py", line 58, in run
    result = self.fn(*self.args, **self.kwargs)
             ^^^^^^^^^^^^^^^^^^^^^^^^^^^^^^^^^^
  File "C:\Users\lucas.melo\traffic-count\venv\Lib\site-packages\flet_core\page.py", line 944, in wrapper
    handler(*args)
  File "C:\Users\lucas.melo\traffic-count\frontend\main.py", line 82, in picker_changed
    adjusted_minutes = (selected.minute // 15) * 15
                        ^^^^^^^^^^^^^^^
AttributeError: 'int' object has no attribute 'minute'
2024-12-17 16:26:44,315 - ERROR - Future exception was never retrieved
future: <Future finished exception=AttributeError("'int' object has no attribute 'minute'")>
Traceback (most recent call last):
  File "C:\Users\lucas.melo\AppData\Local\Programs\Python\Python312\Lib\concurrent\futures\thread.py", line 58, in run
    result = self.fn(*self.args, **self.kwargs)
             ^^^^^^^^^^^^^^^^^^^^^^^^^^^^^^^^^^
  File "C:\Users\lucas.melo\traffic-count\venv\Lib\site-packages\flet_core\page.py", line 944, in wrapper
    handler(*args)
  File "C:\Users\lucas.melo\traffic-count\frontend\main.py", line 82, in picker_changed
    adjusted_minutes = (selected.minute // 15) * 15
                        ^^^^^^^^^^^^^^^
AttributeError: 'int' object has no attribute 'minute'
2024-12-17 16:26:44,398 - ERROR - Future exception was never retrieved
future: <Future finished exception=AttributeError("'int' object has no attribute 'minute'")>
Traceback (most recent call last):
  File "C:\Users\lucas.melo\AppData\Local\Programs\Python\Python312\Lib\concurrent\futures\thread.py", line 58, in run
    result = self.fn(*self.args, **self.kwargs)
             ^^^^^^^^^^^^^^^^^^^^^^^^^^^^^^^^^^
  File "C:\Users\lucas.melo\traffic-count\venv\Lib\site-packages\flet_core\page.py", line 944, in wrapper
    handler(*args)
  File "C:\Users\lucas.melo\traffic-count\frontend\main.py", line 82, in picker_changed
    adjusted_minutes = (selected.minute // 15) * 15
                        ^^^^^^^^^^^^^^^
AttributeError: 'int' object has no attribute 'minute'
2024-12-17 16:26:44,558 - ERROR - Future exception was never retrieved
future: <Future finished exception=AttributeError("'int' object has no attribute 'minute'")>
Traceback (most recent call last):
  File "C:\Users\lucas.melo\AppData\Local\Programs\Python\Python312\Lib\concurrent\futures\thread.py", line 58, in run
    result = self.fn(*self.args, **self.kwargs)
             ^^^^^^^^^^^^^^^^^^^^^^^^^^^^^^^^^^
  File "C:\Users\lucas.melo\traffic-count\venv\Lib\site-packages\flet_core\page.py", line 944, in wrapper
    handler(*args)
  File "C:\Users\lucas.melo\traffic-count\frontend\main.py", line 82, in picker_changed
    adjusted_minutes = (selected.minute // 15) * 15
                        ^^^^^^^^^^^^^^^
AttributeError: 'int' object has no attribute 'minute'
2024-12-17 16:26:44,632 - ERROR - Future exception was never retrieved
future: <Future finished exception=AttributeError("'int' object has no attribute 'minute'")>
Traceback (most recent call last):
  File "C:\Users\lucas.melo\AppData\Local\Programs\Python\Python312\Lib\concurrent\futures\thread.py", line 58, in run
    result = self.fn(*self.args, **self.kwargs)
             ^^^^^^^^^^^^^^^^^^^^^^^^^^^^^^^^^^
  File "C:\Users\lucas.melo\traffic-count\venv\Lib\site-packages\flet_core\page.py", line 944, in wrapper
    handler(*args)
  File "C:\Users\lucas.melo\traffic-count\frontend\main.py", line 82, in picker_changed
    adjusted_minutes = (selected.minute // 15) * 15
                        ^^^^^^^^^^^^^^^
AttributeError: 'int' object has no attribute 'minute'
2024-12-17 16:26:45,210 - ERROR - Future exception was never retrieved
future: <Future finished exception=AttributeError("'int' object has no attribute 'minute'")>
Traceback (most recent call last):
  File "C:\Users\lucas.melo\AppData\Local\Programs\Python\Python312\Lib\concurrent\futures\thread.py", line 58, in run
    result = self.fn(*self.args, **self.kwargs)
             ^^^^^^^^^^^^^^^^^^^^^^^^^^^^^^^^^^
  File "C:\Users\lucas.melo\traffic-count\venv\Lib\site-packages\flet_core\page.py", line 944, in wrapper
    handler(*args)
  File "C:\Users\lucas.melo\traffic-count\frontend\main.py", line 82, in picker_changed
    adjusted_minutes = (selected.minute // 15) * 15
                        ^^^^^^^^^^^^^^^
AttributeError: 'int' object has no attribute 'minute'
2024-12-17 16:26:45,480 - ERROR - Future exception was never retrieved
future: <Future finished exception=AttributeError("'int' object has no attribute 'minute'")>
Traceback (most recent call last):
  File "C:\Users\lucas.melo\AppData\Local\Programs\Python\Python312\Lib\concurrent\futures\thread.py", line 58, in run
    result = self.fn(*self.args, **self.kwargs)
             ^^^^^^^^^^^^^^^^^^^^^^^^^^^^^^^^^^
  File "C:\Users\lucas.melo\traffic-count\venv\Lib\site-packages\flet_core\page.py", line 944, in wrapper
    handler(*args)
  File "C:\Users\lucas.melo\traffic-count\frontend\main.py", line 82, in picker_changed
    adjusted_minutes = (selected.minute // 15) * 15
                        ^^^^^^^^^^^^^^^
AttributeError: 'int' object has no attribute 'minute'
2024-12-17 16:26:45,716 - ERROR - Future exception was never retrieved
future: <Future finished exception=AttributeError("'int' object has no attribute 'minute'")>
Traceback (most recent call last):
  File "C:\Users\lucas.melo\AppData\Local\Programs\Python\Python312\Lib\concurrent\futures\thread.py", line 58, in run
    result = self.fn(*self.args, **self.kwargs)
             ^^^^^^^^^^^^^^^^^^^^^^^^^^^^^^^^^^
  File "C:\Users\lucas.melo\traffic-count\venv\Lib\site-packages\flet_core\page.py", line 944, in wrapper
    handler(*args)
  File "C:\Users\lucas.melo\traffic-count\frontend\main.py", line 82, in picker_changed
    adjusted_minutes = (selected.minute // 15) * 15
                        ^^^^^^^^^^^^^^^
AttributeError: 'int' object has no attribute 'minute'
2024-12-17 16:26:46,418 - ERROR - Future exception was never retrieved
future: <Future finished exception=AttributeError("'int' object has no attribute 'minute'")>
Traceback (most recent call last):
  File "C:\Users\lucas.melo\AppData\Local\Programs\Python\Python312\Lib\concurrent\futures\thread.py", line 58, in run
    result = self.fn(*self.args, **self.kwargs)
             ^^^^^^^^^^^^^^^^^^^^^^^^^^^^^^^^^^
  File "C:\Users\lucas.melo\traffic-count\venv\Lib\site-packages\flet_core\page.py", line 944, in wrapper
    handler(*args)
  File "C:\Users\lucas.melo\traffic-count\frontend\main.py", line 82, in picker_changed
    adjusted_minutes = (selected.minute // 15) * 15
                        ^^^^^^^^^^^^^^^
AttributeError: 'int' object has no attribute 'minute'
2024-12-17 16:26:46,581 - ERROR - Future exception was never retrieved
future: <Future finished exception=AttributeError("'int' object has no attribute 'minute'")>
Traceback (most recent call last):
  File "C:\Users\lucas.melo\AppData\Local\Programs\Python\Python312\Lib\concurrent\futures\thread.py", line 58, in run
    result = self.fn(*self.args, **self.kwargs)
             ^^^^^^^^^^^^^^^^^^^^^^^^^^^^^^^^^^
  File "C:\Users\lucas.melo\traffic-count\venv\Lib\site-packages\flet_core\page.py", line 944, in wrapper
    handler(*args)
  File "C:\Users\lucas.melo\traffic-count\frontend\main.py", line 82, in picker_changed
    adjusted_minutes = (selected.minute // 15) * 15
                        ^^^^^^^^^^^^^^^
AttributeError: 'int' object has no attribute 'minute'
2024-12-17 16:26:46,850 - ERROR - Future exception was never retrieved
future: <Future finished exception=AttributeError("'int' object has no attribute 'minute'")>
Traceback (most recent call last):
  File "C:\Users\lucas.melo\AppData\Local\Programs\Python\Python312\Lib\concurrent\futures\thread.py", line 58, in run
    result = self.fn(*self.args, **self.kwargs)
             ^^^^^^^^^^^^^^^^^^^^^^^^^^^^^^^^^^
  File "C:\Users\lucas.melo\traffic-count\venv\Lib\site-packages\flet_core\page.py", line 944, in wrapper
    handler(*args)
  File "C:\Users\lucas.melo\traffic-count\frontend\main.py", line 82, in picker_changed
    adjusted_minutes = (selected.minute // 15) * 15
                        ^^^^^^^^^^^^^^^
AttributeError: 'int' object has no attribute 'minute'
2024-12-17 16:26:46,925 - ERROR - Future exception was never retrieved
future: <Future finished exception=AttributeError("'int' object has no attribute 'minute'")>
Traceback (most recent call last):
  File "C:\Users\lucas.melo\AppData\Local\Programs\Python\Python312\Lib\concurrent\futures\thread.py", line 58, in run
    result = self.fn(*self.args, **self.kwargs)
             ^^^^^^^^^^^^^^^^^^^^^^^^^^^^^^^^^^
  File "C:\Users\lucas.melo\traffic-count\venv\Lib\site-packages\flet_core\page.py", line 944, in wrapper
    handler(*args)
  File "C:\Users\lucas.melo\traffic-count\frontend\main.py", line 82, in picker_changed
    adjusted_minutes = (selected.minute // 15) * 15
                        ^^^^^^^^^^^^^^^
AttributeError: 'int' object has no attribute 'minute'
2024-12-17 16:26:47,422 - ERROR - Future exception was never retrieved
future: <Future finished exception=AttributeError("'int' object has no attribute 'minute'")>
Traceback (most recent call last):
  File "C:\Users\lucas.melo\AppData\Local\Programs\Python\Python312\Lib\concurrent\futures\thread.py", line 58, in run
    result = self.fn(*self.args, **self.kwargs)
             ^^^^^^^^^^^^^^^^^^^^^^^^^^^^^^^^^^
  File "C:\Users\lucas.melo\traffic-count\venv\Lib\site-packages\flet_core\page.py", line 944, in wrapper
    handler(*args)
  File "C:\Users\lucas.melo\traffic-count\frontend\main.py", line 82, in picker_changed
    adjusted_minutes = (selected.minute // 15) * 15
                        ^^^^^^^^^^^^^^^
AttributeError: 'int' object has no attribute 'minute'
2024-12-17 16:26:47,968 - ERROR - Future exception was never retrieved
future: <Future finished exception=AttributeError("'int' object has no attribute 'minute'")>
Traceback (most recent call last):
  File "C:\Users\lucas.melo\AppData\Local\Programs\Python\Python312\Lib\concurrent\futures\thread.py", line 58, in run
    result = self.fn(*self.args, **self.kwargs)
             ^^^^^^^^^^^^^^^^^^^^^^^^^^^^^^^^^^
  File "C:\Users\lucas.melo\traffic-count\venv\Lib\site-packages\flet_core\page.py", line 944, in wrapper
    handler(*args)
  File "C:\Users\lucas.melo\traffic-count\frontend\main.py", line 82, in picker_changed
    adjusted_minutes = (selected.minute // 15) * 15
                        ^^^^^^^^^^^^^^^
AttributeError: 'int' object has no attribute 'minute'
2024-12-17 16:26:48,189 - ERROR - Future exception was never retrieved
future: <Future finished exception=AttributeError("'int' object has no attribute 'minute'")>
Traceback (most recent call last):
  File "C:\Users\lucas.melo\AppData\Local\Programs\Python\Python312\Lib\concurrent\futures\thread.py", line 58, in run
    result = self.fn(*self.args, **self.kwargs)
             ^^^^^^^^^^^^^^^^^^^^^^^^^^^^^^^^^^
  File "C:\Users\lucas.melo\traffic-count\venv\Lib\site-packages\flet_core\page.py", line 944, in wrapper
    handler(*args)
  File "C:\Users\lucas.melo\traffic-count\frontend\main.py", line 82, in picker_changed
    adjusted_minutes = (selected.minute // 15) * 15
                        ^^^^^^^^^^^^^^^
AttributeError: 'int' object has no attribute 'minute'
2024-12-17 16:26:48,279 - ERROR - Future exception was never retrieved
future: <Future finished exception=AttributeError("'int' object has no attribute 'minute'")>
Traceback (most recent call last):
  File "C:\Users\lucas.melo\AppData\Local\Programs\Python\Python312\Lib\concurrent\futures\thread.py", line 58, in run
    result = self.fn(*self.args, **self.kwargs)
             ^^^^^^^^^^^^^^^^^^^^^^^^^^^^^^^^^^
  File "C:\Users\lucas.melo\traffic-count\venv\Lib\site-packages\flet_core\page.py", line 944, in wrapper
    handler(*args)
  File "C:\Users\lucas.melo\traffic-count\frontend\main.py", line 82, in picker_changed
    adjusted_minutes = (selected.minute // 15) * 15
                        ^^^^^^^^^^^^^^^
AttributeError: 'int' object has no attribute 'minute'
2024-12-17 16:26:48,865 - ERROR - Future exception was never retrieved
future: <Future finished exception=AttributeError("'int' object has no attribute 'minute'")>
Traceback (most recent call last):
  File "C:\Users\lucas.melo\AppData\Local\Programs\Python\Python312\Lib\concurrent\futures\thread.py", line 58, in run
    result = self.fn(*self.args, **self.kwargs)
             ^^^^^^^^^^^^^^^^^^^^^^^^^^^^^^^^^^
  File "C:\Users\lucas.melo\traffic-count\venv\Lib\site-packages\flet_core\page.py", line 944, in wrapper
    handler(*args)
  File "C:\Users\lucas.melo\traffic-count\frontend\main.py", line 82, in picker_changed
    adjusted_minutes = (selected.minute // 15) * 15
                        ^^^^^^^^^^^^^^^
AttributeError: 'int' object has no attribute 'minute'
2024-12-17 16:26:48,938 - ERROR - Future exception was never retrieved
future: <Future finished exception=AttributeError("'int' object has no attribute 'minute'")>
Traceback (most recent call last):
  File "C:\Users\lucas.melo\AppData\Local\Programs\Python\Python312\Lib\concurrent\futures\thread.py", line 58, in run
    result = self.fn(*self.args, **self.kwargs)
             ^^^^^^^^^^^^^^^^^^^^^^^^^^^^^^^^^^
  File "C:\Users\lucas.melo\traffic-count\venv\Lib\site-packages\flet_core\page.py", line 944, in wrapper
    handler(*args)
  File "C:\Users\lucas.melo\traffic-count\frontend\main.py", line 82, in picker_changed
    adjusted_minutes = (selected.minute // 15) * 15
                        ^^^^^^^^^^^^^^^
AttributeError: 'int' object has no attribute 'minute'
2024-12-17 16:26:49,155 - ERROR - Future exception was never retrieved
future: <Future finished exception=AttributeError("'int' object has no attribute 'minute'")>
Traceback (most recent call last):
  File "C:\Users\lucas.melo\AppData\Local\Programs\Python\Python312\Lib\concurrent\futures\thread.py", line 58, in run
    result = self.fn(*self.args, **self.kwargs)
             ^^^^^^^^^^^^^^^^^^^^^^^^^^^^^^^^^^
  File "C:\Users\lucas.melo\traffic-count\venv\Lib\site-packages\flet_core\page.py", line 944, in wrapper
    handler(*args)
  File "C:\Users\lucas.melo\traffic-count\frontend\main.py", line 82, in picker_changed
    adjusted_minutes = (selected.minute // 15) * 15
                        ^^^^^^^^^^^^^^^
AttributeError: 'int' object has no attribute 'minute'
2024-12-17 16:26:49,235 - ERROR - Future exception was never retrieved
future: <Future finished exception=AttributeError("'int' object has no attribute 'minute'")>
Traceback (most recent call last):
  File "C:\Users\lucas.melo\AppData\Local\Programs\Python\Python312\Lib\concurrent\futures\thread.py", line 58, in run
    result = self.fn(*self.args, **self.kwargs)
             ^^^^^^^^^^^^^^^^^^^^^^^^^^^^^^^^^^
  File "C:\Users\lucas.melo\traffic-count\venv\Lib\site-packages\flet_core\page.py", line 944, in wrapper
    handler(*args)
  File "C:\Users\lucas.melo\traffic-count\frontend\main.py", line 82, in picker_changed
    adjusted_minutes = (selected.minute // 15) * 15
                        ^^^^^^^^^^^^^^^
AttributeError: 'int' object has no attribute 'minute'
2024-12-17 16:26:50,233 - ERROR - Future exception was never retrieved
future: <Future finished exception=AttributeError("'int' object has no attribute 'minute'")>
Traceback (most recent call last):
  File "C:\Users\lucas.melo\AppData\Local\Programs\Python\Python312\Lib\concurrent\futures\thread.py", line 58, in run
    result = self.fn(*self.args, **self.kwargs)
             ^^^^^^^^^^^^^^^^^^^^^^^^^^^^^^^^^^
  File "C:\Users\lucas.melo\traffic-count\venv\Lib\site-packages\flet_core\page.py", line 944, in wrapper
    handler(*args)
  File "C:\Users\lucas.melo\traffic-count\frontend\main.py", line 82, in picker_changed
    adjusted_minutes = (selected.minute // 15) * 15
                        ^^^^^^^^^^^^^^^
AttributeError: 'int' object has no attribute 'minute'
2024-12-17 16:26:50,411 - ERROR - Future exception was never retrieved
future: <Future finished exception=AttributeError("'int' object has no attribute 'minute'")>
Traceback (most recent call last):
  File "C:\Users\lucas.melo\AppData\Local\Programs\Python\Python312\Lib\concurrent\futures\thread.py", line 58, in run
    result = self.fn(*self.args, **self.kwargs)
             ^^^^^^^^^^^^^^^^^^^^^^^^^^^^^^^^^^
  File "C:\Users\lucas.melo\traffic-count\venv\Lib\site-packages\flet_core\page.py", line 944, in wrapper
    handler(*args)
  File "C:\Users\lucas.melo\traffic-count\frontend\main.py", line 82, in picker_changed
    adjusted_minutes = (selected.minute // 15) * 15
                        ^^^^^^^^^^^^^^^
AttributeError: 'int' object has no attribute 'minute'
2024-12-17 16:27:19,407 - ERROR - Future exception was never retrieved
future: <Future finished exception=AttributeError("'int' object has no attribute 'minute'")>
Traceback (most recent call last):
  File "C:\Users\lucas.melo\AppData\Local\Programs\Python\Python312\Lib\concurrent\futures\thread.py", line 58, in run
    result = self.fn(*self.args, **self.kwargs)
             ^^^^^^^^^^^^^^^^^^^^^^^^^^^^^^^^^^
  File "C:\Users\lucas.melo\traffic-count\venv\Lib\site-packages\flet_core\page.py", line 944, in wrapper
    handler(*args)
  File "C:\Users\lucas.melo\traffic-count\frontend\main.py", line 82, in picker_changed
    adjusted_minutes = (selected.minute // 15) * 15
                        ^^^^^^^^^^^^^^^
AttributeError: 'int' object has no attribute 'minute'
2024-12-17 16:27:20,877 - ERROR - Future exception was never retrieved
future: <Future finished exception=AttributeError("'int' object has no attribute 'minute'")>
Traceback (most recent call last):
  File "C:\Users\lucas.melo\AppData\Local\Programs\Python\Python312\Lib\concurrent\futures\thread.py", line 58, in run
    result = self.fn(*self.args, **self.kwargs)
             ^^^^^^^^^^^^^^^^^^^^^^^^^^^^^^^^^^
  File "C:\Users\lucas.melo\traffic-count\venv\Lib\site-packages\flet_core\page.py", line 944, in wrapper
    handler(*args)
  File "C:\Users\lucas.melo\traffic-count\frontend\main.py", line 82, in picker_changed
    adjusted_minutes = (selected.minute // 15) * 15
                        ^^^^^^^^^^^^^^^
AttributeError: 'int' object has no attribute 'minute'
2024-12-17 16:27:22,067 - ERROR - Future exception was never retrieved
future: <Future finished exception=AttributeError("'int' object has no attribute 'minute'")>
Traceback (most recent call last):
  File "C:\Users\lucas.melo\AppData\Local\Programs\Python\Python312\Lib\concurrent\futures\thread.py", line 58, in run
    result = self.fn(*self.args, **self.kwargs)
             ^^^^^^^^^^^^^^^^^^^^^^^^^^^^^^^^^^
  File "C:\Users\lucas.melo\traffic-count\venv\Lib\site-packages\flet_core\page.py", line 944, in wrapper
    handler(*args)
  File "C:\Users\lucas.melo\traffic-count\frontend\main.py", line 82, in picker_changed
    adjusted_minutes = (selected.minute // 15) * 15
                        ^^^^^^^^^^^^^^^
AttributeError: 'int' object has no attribute 'minute'
2024-12-17 16:28:18,802 - ERROR - Future exception was never retrieved
future: <Future finished exception=TypeError("ContadorPerplan.setup_aba_inicio.<locals>.picker_changed() missing 1 required positional argument: 'e'")>
Traceback (most recent call last):
  File "C:\Users\lucas.melo\AppData\Local\Programs\Python\Python312\Lib\concurrent\futures\thread.py", line 58, in run
    result = self.fn(*self.args, **self.kwargs)
             ^^^^^^^^^^^^^^^^^^^^^^^^^^^^^^^^^^
  File "C:\Users\lucas.melo\traffic-count\venv\Lib\site-packages\flet_core\page.py", line 944, in wrapper
    handler(*args)
TypeError: ContadorPerplan.setup_aba_inicio.<locals>.picker_changed() missing 1 required positional argument: 'e'
2024-12-17 16:28:20,019 - ERROR - Future exception was never retrieved
future: <Future finished exception=TypeError("ContadorPerplan.setup_aba_inicio.<locals>.picker_changed() missing 1 required positional argument: 'e'")>
Traceback (most recent call last):
  File "C:\Users\lucas.melo\AppData\Local\Programs\Python\Python312\Lib\concurrent\futures\thread.py", line 58, in run
    result = self.fn(*self.args, **self.kwargs)
             ^^^^^^^^^^^^^^^^^^^^^^^^^^^^^^^^^^
  File "C:\Users\lucas.melo\traffic-count\venv\Lib\site-packages\flet_core\page.py", line 944, in wrapper
    handler(*args)
TypeError: ContadorPerplan.setup_aba_inicio.<locals>.picker_changed() missing 1 required positional argument: 'e'
2024-12-17 16:28:20,551 - ERROR - Future exception was never retrieved
future: <Future finished exception=TypeError("ContadorPerplan.setup_aba_inicio.<locals>.picker_changed() missing 1 required positional argument: 'e'")>
Traceback (most recent call last):
  File "C:\Users\lucas.melo\AppData\Local\Programs\Python\Python312\Lib\concurrent\futures\thread.py", line 58, in run
    result = self.fn(*self.args, **self.kwargs)
             ^^^^^^^^^^^^^^^^^^^^^^^^^^^^^^^^^^
  File "C:\Users\lucas.melo\traffic-count\venv\Lib\site-packages\flet_core\page.py", line 944, in wrapper
    handler(*args)
TypeError: ContadorPerplan.setup_aba_inicio.<locals>.picker_changed() missing 1 required positional argument: 'e'
2024-12-17 16:29:23,302 - ERROR - Future exception was never retrieved
future: <Future finished exception=TypeError("unsupported operand type(s) for divmod(): 'ControlEvent' and 'int'")>
Traceback (most recent call last):
  File "C:\Users\lucas.melo\AppData\Local\Programs\Python\Python312\Lib\concurrent\futures\thread.py", line 58, in run
    result = self.fn(*self.args, **self.kwargs)
             ^^^^^^^^^^^^^^^^^^^^^^^^^^^^^^^^^^
  File "C:\Users\lucas.melo\traffic-count\venv\Lib\site-packages\flet_core\page.py", line 944, in wrapper
    handler(*args)
  File "C:\Users\lucas.melo\traffic-count\frontend\main.py", line 82, in picker_changed
    hours, remainder = divmod(selected_seconds, 3600)  # Converte para horas e o restante
                       ^^^^^^^^^^^^^^^^^^^^^^^^^^^^^^
TypeError: unsupported operand type(s) for divmod(): 'ControlEvent' and 'int'
2024-12-17 16:33:31,267 - ERROR - Erro ao carregar tokens salvos: type object 'CupertinoTimerPickerMode' has no attribute 'HM'
2024-12-18 10:17:03,202 - ERROR - Future exception was never retrieved
future: <Future finished exception=AttributeError("'ContadorPerplan' object has no attribute 'inicio_input'")>
Traceback (most recent call last):
  File "C:\Users\lucas.melo\AppData\Local\Programs\Python\Python312\Lib\concurrent\futures\thread.py", line 58, in run
    result = self.fn(*self.args, **self.kwargs)
             ^^^^^^^^^^^^^^^^^^^^^^^^^^^^^^^^^^
  File "C:\Users\lucas.melo\traffic-count\venv\Lib\site-packages\flet_core\page.py", line 944, in wrapper
    handler(*args)
  File "C:\Users\lucas.melo\traffic-count\frontend\main.py", line 140, in criar_sessao
    sessao.criar_sessao(self, e)
  File "C:\Users\lucas.melo\traffic-count\frontend\app\sessao.py", line 16, in criar_sessao
    if not self.validar_campos():
           ^^^^^^^^^^^^^^^^^^^^^
  File "C:\Users\lucas.melo\traffic-count\frontend\main.py", line 205, in validar_campos
    (self.inicio_input, "Horário de Início"),
     ^^^^^^^^^^^^^^^^^
AttributeError: 'ContadorPerplan' object has no attribute 'inicio_input'
2024-12-18 10:18:48,958 - ERROR - Future exception was never retrieved
future: <Future finished exception=ValueError('list.remove(x): x not in list')>
Traceback (most recent call last):
  File "C:\Users\lucas.melo\AppData\Local\Programs\Python\Python312\Lib\concurrent\futures\thread.py", line 58, in run
    result = self.fn(*self.args, **self.kwargs)
             ^^^^^^^^^^^^^^^^^^^^^^^^^^^^^^^^^^
  File "C:\Users\lucas.melo\traffic-count\venv\Lib\site-packages\flet_core\page.py", line 944, in wrapper
    handler(*args)
  File "C:\Users\lucas.melo\traffic-count\frontend\main.py", line 104, in <lambda>
    on_click=lambda _: remover_campo_movimento(movimento_input, remover_button)
                       ^^^^^^^^^^^^^^^^^^^^^^^^^^^^^^^^^^^^^^^^^^^^^^^^^^^^^^^^
  File "C:\Users\lucas.melo\traffic-count\frontend\main.py", line 112, in remover_campo_movimento
    self.movimentos_container.controls.remove(
ValueError: list.remove(x): x not in list
2024-12-18 10:18:49,860 - ERROR - Future exception was never retrieved
future: <Future finished exception=ValueError('list.remove(x): x not in list')>
Traceback (most recent call last):
  File "C:\Users\lucas.melo\AppData\Local\Programs\Python\Python312\Lib\concurrent\futures\thread.py", line 58, in run
    result = self.fn(*self.args, **self.kwargs)
             ^^^^^^^^^^^^^^^^^^^^^^^^^^^^^^^^^^
  File "C:\Users\lucas.melo\traffic-count\venv\Lib\site-packages\flet_core\page.py", line 944, in wrapper
    handler(*args)
  File "C:\Users\lucas.melo\traffic-count\frontend\main.py", line 104, in <lambda>
    on_click=lambda _: remover_campo_movimento(movimento_input, remover_button)
                       ^^^^^^^^^^^^^^^^^^^^^^^^^^^^^^^^^^^^^^^^^^^^^^^^^^^^^^^^
  File "C:\Users\lucas.melo\traffic-count\frontend\main.py", line 112, in remover_campo_movimento
    self.movimentos_container.controls.remove(
ValueError: list.remove(x): x not in list
2024-12-18 10:19:15,264 - ERROR - Future exception was never retrieved
future: <Future finished exception=AttributeError("'ContadorPerplan' object has no attribute 'inicio_input'")>
Traceback (most recent call last):
  File "C:\Users\lucas.melo\AppData\Local\Programs\Python\Python312\Lib\concurrent\futures\thread.py", line 58, in run
    result = self.fn(*self.args, **self.kwargs)
             ^^^^^^^^^^^^^^^^^^^^^^^^^^^^^^^^^^
  File "C:\Users\lucas.melo\traffic-count\venv\Lib\site-packages\flet_core\page.py", line 944, in wrapper
    handler(*args)
  File "C:\Users\lucas.melo\traffic-count\frontend\main.py", line 140, in criar_sessao
    sessao.criar_sessao(self, e)
  File "C:\Users\lucas.melo\traffic-count\frontend\app\sessao.py", line 16, in criar_sessao
    if not self.validar_campos():
           ^^^^^^^^^^^^^^^^^^^^^
  File "C:\Users\lucas.melo\traffic-count\frontend\main.py", line 205, in validar_campos
    (self.inicio_input, "Horário de Início"),
     ^^^^^^^^^^^^^^^^^
AttributeError: 'ContadorPerplan' object has no attribute 'inicio_input'
2024-12-18 10:19:19,523 - ERROR - Future exception was never retrieved
future: <Future finished exception=ValueError('list.remove(x): x not in list')>
Traceback (most recent call last):
  File "C:\Users\lucas.melo\AppData\Local\Programs\Python\Python312\Lib\concurrent\futures\thread.py", line 58, in run
    result = self.fn(*self.args, **self.kwargs)
             ^^^^^^^^^^^^^^^^^^^^^^^^^^^^^^^^^^
  File "C:\Users\lucas.melo\traffic-count\venv\Lib\site-packages\flet_core\page.py", line 944, in wrapper
    handler(*args)
  File "C:\Users\lucas.melo\traffic-count\frontend\main.py", line 104, in <lambda>
    on_click=lambda _: remover_campo_movimento(movimento_input, remover_button)
                       ^^^^^^^^^^^^^^^^^^^^^^^^^^^^^^^^^^^^^^^^^^^^^^^^^^^^^^^^
  File "C:\Users\lucas.melo\traffic-count\frontend\main.py", line 112, in remover_campo_movimento
    self.movimentos_container.controls.remove(
ValueError: list.remove(x): x not in list
2024-12-18 10:32:36,262 - ERROR - Future exception was never retrieved
future: <Future finished exception=AttributeError("'ContadorPerplan' object has no attribute 'inicio_input'")>
Traceback (most recent call last):
  File "C:\Users\lucas.melo\AppData\Local\Programs\Python\Python312\Lib\concurrent\futures\thread.py", line 58, in run
    result = self.fn(*self.args, **self.kwargs)
             ^^^^^^^^^^^^^^^^^^^^^^^^^^^^^^^^^^
  File "C:\Users\lucas.melo\traffic-count\venv\Lib\site-packages\flet_core\page.py", line 944, in wrapper
    handler(*args)
  File "C:\Users\lucas.melo\traffic-count\frontend\main.py", line 185, in criar_sessao
    sessao.criar_sessao(self, e)
  File "C:\Users\lucas.melo\traffic-count\frontend\app\sessao.py", line 16, in criar_sessao
    if not self.validar_campos():
           ^^^^^^^^^^^^^^^^^^^^^
  File "C:\Users\lucas.melo\traffic-count\frontend\main.py", line 250, in validar_campos
    (self.inicio_input, "Horário de Início"),
     ^^^^^^^^^^^^^^^^^
AttributeError: 'ContadorPerplan' object has no attribute 'inicio_input'
2024-12-18 10:52:19,376 - ERROR - Future exception was never retrieved
future: <Future finished exception=AttributeError("'ContadorPerplan' object has no attribute 'inicio_input'")>
Traceback (most recent call last):
  File "C:\Users\lucas.melo\AppData\Local\Programs\Python\Python312\Lib\concurrent\futures\thread.py", line 58, in run
    result = self.fn(*self.args, **self.kwargs)
             ^^^^^^^^^^^^^^^^^^^^^^^^^^^^^^^^^^
  File "C:\Users\lucas.melo\traffic-count\venv\Lib\site-packages\flet_core\page.py", line 944, in wrapper
    handler(*args)
  File "C:\Users\lucas.melo\traffic-count\frontend\main.py", line 185, in criar_sessao
    sessao.criar_sessao(self, e)
  File "C:\Users\lucas.melo\traffic-count\frontend\app\sessao.py", line 16, in criar_sessao
    if not self.validar_campos():
           ^^^^^^^^^^^^^^^^^^^^^
  File "C:\Users\lucas.melo\traffic-count\frontend\main.py", line 250, in validar_campos
    (self.inicio_input, "Horário de Início"),
     ^^^^^^^^^^^^^^^^^
AttributeError: 'ContadorPerplan' object has no attribute 'inicio_input'
2024-12-18 10:53:21,959 - ERROR - Erro ao criar sessão: name 'original_date' is not defined
2024-12-18 10:58:09,216 - ERROR - Erro ao criar sessão: 'ContadorPerplan' object has no attribute 'padrao_dropdown'
2024-12-18 11:03:18,063 - ERROR - Erro ao criar sessão: 'ContadorPerplan' object has no attribute 'sessao_status'
2024-12-18 11:03:22,212 - ERROR - Erro ao criar sessão: 'ContadorPerplan' object has no attribute 'sessao_status'
2024-12-18 11:04:12,103 - ERROR - Erro ao criar sessão: 'ContadorPerplan' object has no attribute 'sessao_status'
2024-12-18 11:04:19,048 - ERROR - Erro ao carregar sessão ativa: 'ContadorPerplan' object has no attribute 'sessao_status'
2024-12-18 11:05:10,382 - ERROR - Erro ao carregar sessão ativa: 'ContadorPerplan' object has no attribute 'padrao_dropdown'
2024-12-18 11:05:19,801 - ERROR - Erro ao criar sessão: 'ContadorPerplan' object has no attribute 'padrao_dropdown'
2024-12-18 11:13:30,917 - ERROR - Erro ao carregar tokens salvos: module 'flet_core.icons' has no attribute 'CLOCK'
2024-12-18 11:19:49,058 - ERROR - Erro ao carregar tokens salvos: ElevatedButton.__init__() got an unexpected keyword argument 'border_radius'
2024-12-18 13:58:13,151 - ERROR - Erro ao carregar tokens salvos: Text.__init__() got an unexpected keyword argument 'align'
2024-12-18 13:58:24,966 - ERROR - Erro ao carregar tokens salvos: Text.__init__() got an unexpected keyword argument 'alignment'
2024-12-18 14:03:39,874 - ERROR - Erro ao carregar tokens salvos: 'mappingproxy' object has no attribute '__dict__'
2024-12-18 14:12:20,384 - ERROR - Erro ao carregar tokens salvos: TextField.__init__() got an unexpected keyword argument 'marginy'
2024-12-18 14:13:46,548 - ERROR - Erro ao carregar tokens salvos: TextField.__init__() got an unexpected keyword argument 'margin'
2024-12-18 14:13:55,704 - ERROR - Erro ao carregar tokens salvos: TextField.__init__() got an unexpected keyword argument 'padding'
2024-12-18 14:19:47,126 - ERROR - Erro ao carregar tokens salvos: Switch.__init__() got an unexpected keyword argument 'inactive_color'
2024-12-18 14:21:38,301 - ERROR - Erro ao carregar sessão ativa: time data 'Horário: 03:00' does not match format '%H:%M'
2024-12-18 14:21:57,677 - ERROR - Erro ao carregar sessão ativa: time data 'Horário: 03:00' does not match format '%H:%M'
2024-12-18 14:22:16,622 - ERROR - Erro ao carregar sessão ativa: time data 'Horário: 03:00' does not match format '%H:%M'
2024-12-18 14:27:22,922 - ERROR - Erro ao carregar sessão ativa: ElevatedButton Control must be added to the page first
2024-12-18 14:27:53,332 - ERROR - Erro ao salvar contagens: 'ContadorPerplan' object has no attribute 'inicio_input'
2024-12-18 14:27:53,333 - ERROR - Erro ao salvar contagens: 'ContadorPerplan' object has no attribute 'inicio_input'
2024-12-18 14:37:04,414 - ERROR - Erro ao carregar sessão ativa: ElevatedButton Control must be added to the page first
2024-12-18 14:39:07,692 - ERROR - Erro ao carregar sessão ativa: ElevatedButton Control must be added to the page first
2024-12-18 14:44:57,992 - ERROR - Erro ao salvar contagens: time data 'Horário: 09:00' does not match format '%H:%M'
2024-12-18 14:44:57,993 - ERROR - Erro ao salvar contagens: time data 'Horário: 09:00' does not match format '%H:%M'
2024-12-18 14:49:09,480 - ERROR - Erro ao carregar sessão ativa: Detalhes da sessão não contêm 'Periodo'.
2024-12-18 15:24:28,091 - ERROR - Erro ao carregar sessão ativa: Detalhes da sessão não contêm 'Periodo'.
2024-12-18 15:24:56,757 - ERROR - Erro ao carregar sessão ativa: Detalhes da sessão não contêm 'Periodo'.
2024-12-18 15:26:57,239 - ERROR - Erro ao carregar sessão ativa: ElevatedButton Control must be added to the page first
2024-12-18 15:29:32,341 - ERROR - Erro ao carregar sessão ativa: ElevatedButton Control must be added to the page first
2024-12-18 15:33:44,988 - ERROR - Erro ao carregar sessão ativa: ElevatedButton Control must be added to the page first
2024-12-18 15:39:55,462 - ERROR - Erro ao carregar sessão ativa: ElevatedButton Control must be added to the page first
2024-12-18 15:40:43,369 - ERROR - Erro ao carregar sessão ativa: ElevatedButton Control must be added to the page first
2024-12-18 15:42:48,013 - ERROR - Erro ao carregar sessão ativa: ElevatedButton Control must be added to the page first
2024-12-18 15:45:53,476 - ERROR - Erro ao carregar sessão ativa: ElevatedButton Control must be added to the page first
2024-12-18 15:49:39,318 - ERROR - Erro ao carregar sessão ativa: ElevatedButton Control must be added to the page first
2024-12-18 15:49:59,080 - ERROR - Erro ao carregar sessão ativa: ElevatedButton Control must be added to the page first
2024-12-18 15:50:16,386 - ERROR - Erro ao carregar sessão ativa: ElevatedButton Control must be added to the page first
2024-12-18 16:11:27,808 - ERROR - Erro ao salvar contagens: 'NoneType' object has no attribute 'strftime'
2024-12-18 16:11:27,809 - ERROR - Erro ao pressionar tecla: 'NoneType' object has no attribute 'strftime'
2024-12-18 16:11:28,435 - ERROR - Erro ao salvar contagens: 'NoneType' object has no attribute 'strftime'
2024-12-18 16:11:28,436 - ERROR - Erro ao pressionar tecla: 'NoneType' object has no attribute 'strftime'
2024-12-18 16:11:28,908 - ERROR - Erro ao salvar contagens: 'NoneType' object has no attribute 'strftime'
2024-12-18 16:11:28,908 - ERROR - Erro ao pressionar tecla: 'NoneType' object has no attribute 'strftime'
2024-12-18 16:11:29,568 - ERROR - Erro ao salvar contagens: 'NoneType' object has no attribute 'strftime'
2024-12-18 16:11:29,569 - ERROR - Erro ao pressionar tecla: 'NoneType' object has no attribute 'strftime'
2024-12-18 16:11:29,973 - ERROR - Erro ao salvar contagens: 'NoneType' object has no attribute 'strftime'
2024-12-18 16:11:29,974 - ERROR - Erro ao pressionar tecla: 'NoneType' object has no attribute 'strftime'
2024-12-18 16:11:30,658 - ERROR - Erro ao salvar contagens: 'NoneType' object has no attribute 'strftime'
2024-12-18 16:11:30,659 - ERROR - Erro ao pressionar tecla: 'NoneType' object has no attribute 'strftime'
2024-12-18 16:11:31,110 - ERROR - Erro ao salvar contagens: 'NoneType' object has no attribute 'strftime'
2024-12-18 16:11:31,111 - ERROR - Erro ao pressionar tecla: 'NoneType' object has no attribute 'strftime'
2024-12-18 16:11:31,724 - ERROR - Erro ao salvar contagens: 'NoneType' object has no attribute 'strftime'
2024-12-18 16:11:31,725 - ERROR - Erro ao pressionar tecla: 'NoneType' object has no attribute 'strftime'
2024-12-18 16:11:38,853 - ERROR - Erro ao salvar contagens: 'NoneType' object has no attribute 'strftime'
2024-12-18 16:11:38,854 - ERROR - Erro ao pressionar tecla: 'NoneType' object has no attribute 'strftime'
2024-12-18 16:11:40,320 - ERROR - Erro ao salvar contagens: 'NoneType' object has no attribute 'strftime'
2024-12-18 16:11:40,321 - ERROR - Erro ao pressionar tecla: 'NoneType' object has no attribute 'strftime'
2024-12-18 16:11:40,843 - ERROR - Erro ao salvar contagens: 'NoneType' object has no attribute 'strftime'
2024-12-18 16:11:40,843 - ERROR - Erro ao pressionar tecla: 'NoneType' object has no attribute 'strftime'
2024-12-21 11:56:23,512 - ERROR - Erro ao salvar contagens: This session is in 'prepared' state; no further SQL can be emitted within this transaction.
2024-12-21 11:56:23,533 - ERROR - Future exception was never retrieved
future: <Future finished exception=InvalidRequestError("This session is in 'prepared' state; no further SQL can be emitted within this transaction.")>
Traceback (most recent call last):
  File "C:\Users\lucas.melo\AppData\Local\Programs\Python\Python312\Lib\concurrent\futures\thread.py", line 58, in run
    result = self.fn(*self.args, **self.kwargs)
             ^^^^^^^^^^^^^^^^^^^^^^^^^^^^^^^^^^
  File "C:\Users\lucas.melo\traffic-count\venv\Lib\site-packages\flet_core\page.py", line 944, in wrapper
    handler(*args)
  File "C:\Users\lucas.melo\traffic-count\frontend\main.py", line 413, in on_confirm_save
    self._perform_save(now)
  File "C:\Users\lucas.melo\traffic-count\frontend\main.py", line 466, in _perform_save
    for categoria in [c for c in self.categorias if c.movimento == movimento]:
                                                    ^^^^^^^^^^^
  File "C:\Users\lucas.melo\traffic-count\venv\Lib\site-packages\sqlalchemy\orm\attributes.py", line 566, in __get__
    return self.impl.get(state, dict_)  # type: ignore[no-any-return]
           ^^^^^^^^^^^^^^^^^^^^^^^^^^^
  File "C:\Users\lucas.melo\traffic-count\venv\Lib\site-packages\sqlalchemy\orm\attributes.py", line 1086, in get
    value = self._fire_loader_callables(state, key, passive)
            ^^^^^^^^^^^^^^^^^^^^^^^^^^^^^^^^^^^^^^^^^^^^^^^^
  File "C:\Users\lucas.melo\traffic-count\venv\Lib\site-packages\sqlalchemy\orm\attributes.py", line 1116, in _fire_loader_callables
    return state._load_expired(state, passive)
           ^^^^^^^^^^^^^^^^^^^^^^^^^^^^^^^^^^^
  File "C:\Users\lucas.melo\traffic-count\venv\Lib\site-packages\sqlalchemy\orm\state.py", line 803, in _load_expired
    self.manager.expired_attribute_loader(self, toload, passive)
  File "C:\Users\lucas.melo\traffic-count\venv\Lib\site-packages\sqlalchemy\orm\loading.py", line 1670, in load_scalar_attributes
    result = load_on_ident(
             ^^^^^^^^^^^^^^
  File "C:\Users\lucas.melo\traffic-count\venv\Lib\site-packages\sqlalchemy\orm\loading.py", line 509, in load_on_ident
    return load_on_pk_identity(
           ^^^^^^^^^^^^^^^^^^^^
  File "C:\Users\lucas.melo\traffic-count\venv\Lib\site-packages\sqlalchemy\orm\loading.py", line 694, in load_on_pk_identity
    session.execute(
  File "C:\Users\lucas.melo\traffic-count\venv\Lib\site-packages\sqlalchemy\orm\session.py", line 2362, in execute
    return self._execute_internal(
           ^^^^^^^^^^^^^^^^^^^^^^^
  File "C:\Users\lucas.melo\traffic-count\venv\Lib\site-packages\sqlalchemy\orm\session.py", line 2237, in _execute_internal
    conn = self._connection_for_bind(bind)
           ^^^^^^^^^^^^^^^^^^^^^^^^^^^^^^^
  File "C:\Users\lucas.melo\traffic-count\venv\Lib\site-packages\sqlalchemy\orm\session.py", line 2106, in _connection_for_bind
    return trans._connection_for_bind(engine, execution_options)
           ^^^^^^^^^^^^^^^^^^^^^^^^^^^^^^^^^^^^^^^^^^^^^^^^^^^^^
  File "<string>", line 2, in _connection_for_bind
  File "C:\Users\lucas.melo\traffic-count\venv\Lib\site-packages\sqlalchemy\orm\state_changes.py", line 103, in _go
    self._raise_for_prerequisite_state(fn.__name__, current_state)
  File "C:\Users\lucas.melo\traffic-count\venv\Lib\site-packages\sqlalchemy\orm\session.py", line 996, in _raise_for_prerequisite_state
    raise sa_exc.InvalidRequestError(
sqlalchemy.exc.InvalidRequestError: This session is in 'prepared' state; no further SQL can be emitted within this transaction.
2024-12-21 12:04:26,437 - ERROR - Erro ao salvar contagens: [Errno 2] No such file or directory: 'Z:\\\\0Pesquisa\\\\_0ContadorDigital\\\\Contagens\\lucas.melo\\Teste\\P10_21-12-2024_Horárioh 12h45.xlsx'
2024-12-21 12:04:26,438 - ERROR - Erro ao salvar contagens: [Errno 2] No such file or directory: 'Z:\\\\0Pesquisa\\\\_0ContadorDigital\\\\Contagens\\lucas.melo\\Teste\\P10_21-12-2024_Horárioh 12h45.xlsx'
2024-12-21 12:06:27,524 - ERROR - Erro ao salvar sessão: This session is in 'prepared' state; no further SQL can be emitted within this transaction.
2024-12-21 12:06:27,551 - ERROR - Erro ao salvar no DB: Method 'rollback()' can't be called here; method 'rollback()' is already in progress and this would cause an unexpected state change to <SessionTransactionState.CLOSED: 5> (Background on this error at: https://sqlalche.me/e/20/isce)
2024-12-21 12:06:27,551 - ERROR - Erro ao incrementar: Method 'rollback()' can't be called here; method 'rollback()' is already in progress and this would cause an unexpected state change to <SessionTransactionState.CLOSED: 5> (Background on this error at: https://sqlalche.me/e/20/isce)
2024-12-21 13:24:06,028 - ERROR - Erro ao salvar contagens: 'ContadorPerplan' object has no attribute 'current_timeslot'
2024-12-21 13:24:06,029 - ERROR - Erro ao salvar contagens: 'ContadorPerplan' object has no attribute 'current_timeslot'
2024-12-21 14:07:01,870 - ERROR - Erro ao salvar contagens: Event loop is closed
